Workbook

Sheet ESTOQUE SUL - RS
A1: Nome do Responsável Estoque - Tst ou Eng.: Luis Martins
A2: Data da atualização da Planilha: 24/07/2026
A3: Estoque da Cidade/Base: Porto Alegre/RS
A4: Nº | B4: DESCRIÇÃO | C4: R$ /item | D4: TAM. | E4: QTD | F4: R$ /estoque | G4: OBS.:
A5: =ROW()-4 -> 1 | B5: BALDE DE LONA | C5: ='ESTOQUE - SPO'!D6 -> 126.1 | D5: - | E5: 0 | F5: =C5*E5 -> 0 | G5: REPOR ESTOQUE
A6: =ROW()-4 -> 2 | B6: BANDEROLA PARA ESCADA | C6: ='ESTOQUE - SPO'!#REF! -> #REF! | D6: - | E6: 50
A7: =ROW()-4 -> 3 | B7: BOTA DE PVC | C7: 65.13 | D7: 37 | E7: 10 | F7: =E7*C7 -> 651.3
A8: =ROW()-4 -> 4 | B8: BOTA DE PVC | C8: 65.13 | D8: 38 | E8: 12 | F8: =E8*C8 -> 781.56
A9: =ROW()-4 -> 5 | B9: BOTA DE PVC | C9: 65.13 | D9: 39 | E9: 8 | F9: =E9*C9 -> 521.04
A10: =ROW()-4 -> 6 | B10: BOTA DE PVC | C10: 65.13 | D10: 41 | E10: 6 | F10: =E10*C10 -> 390.78
A11: =ROW()-4 -> 7 | B11: BOTINA DE SEGURANÇA 34 | C11: 104.29 | D11: 34 | E11: 0 | F11: =E11*C11 -> 0 | G11: REPOR ESTOQUE
A12: =ROW()-4 -> 8 | B12: BOTINA DE SEGURANÇA 35 | C12: 104.29 | D12: 35 | E12: 0 | F12: =E12*C12 -> 0 | G12: REPOR ESTOQUE
A13: =ROW()-4 -> 9 | B13: BOTINA DE SEGURANÇA 36 | C13: ='ESTOQUE - SPO'!D18 -> 104.29 | D13: 36 | E13: 9 | F13: =E13*C13 -> 938.61
A14: =ROW()-4 -> 10 | B14: BOTINA DE SEGURANÇA 37 | C14: ='ESTOQUE - SPO'!D19 -> 104.29 | D14: 37 | E14: 15 | F14: =E14*C14 -> 1564.35
A15: =ROW()-4 -> 11 | B15: BOTINA DE SEGURANÇA 38 | C15: ='ESTOQUE - SPO'!D20 -> 104.29 | D15: 38 | E15: 18 | F15: =E15*C15 -> 1877.22
A16: =ROW()-4 -> 12 | B16: BOTINA DE SEGURANÇA 39 | C16: ='ESTOQUE - SPO'!D21 -> 104.29 | D16: 39 | E16: 28 | F16: =E16*C16 -> 2920.12
A17: =ROW()-4 -> 13 | B17: BOTINA DE SEGURANÇA 40 | C17: ='ESTOQUE - SPO'!D22 -> 104.29 | D17: 40 | E17: 15 | F17: =E17*C17 -> 1564.35
A18: =ROW()-4 -> 14 | B18: BOTINA DE SEGURANÇA 41 | C18: ='ESTOQUE - SPO'!D23 -> 104.29 | D18: 41 | E18: 11 | F18: =E18*C18 -> 1147.19
A19: =ROW()-4 -> 15 | B19: BOTINA DE SEGURANÇA 42 | C19: ='ESTOQUE - SPO'!D24 -> 104.29 | D19: 42 | E19: 5 | F19: =E19*C19 -> 521.45
A20: =ROW()-4 -> 16 | B20: BOTINA DE SEGURANÇA 43 | C20: ='ESTOQUE - SPO'!D25 -> 104.29 | D20: 43 | E20: 12 | F20: =E20*C20 -> 1251.48
A21: =ROW()-4 -> 17 | B21: BOTINA DE SEGURANÇA 44 | C21: ='ESTOQUE - SPO'!D26 -> 104.29 | D21: 44 | E21: 14 | F21: =E21*C21 -> 1460.06
A22: =ROW()-4 -> 18 | B22: BOTINA DE SEGURANÇA 45 | C22: ='ESTOQUE - SPO'!D27 -> 104.29 | D22: 45 | E22: 0 | F22: =E22*C22 -> 0 | G22: REPOR ESTOQUE
A23: =ROW()-4 -> 19 | B23: CALÇA IMPERMEÁVEL PVC | C23: 32.55 | D23: M | E23: 10 | F23: =E23*C23 -> 325.5
A24: =ROW()-4 -> 20 | B24: CALÇA IMPERMEÁVEL PVC | C24: 32.55 | D24: G | E24: 7 | F24: =E24*C24 -> 227.85
A25: =ROW()-4 -> 21 | B25: CALÇA IMPERMEÁVEL PVC | C25: 32.55 | D25: P | E25: 10 | F25: =E25*C25 -> 325.5
A26: =ROW()-4 -> 22 | B26: CALÇA IMPERMEÁVEL PVC | C26: 32.55 | D26: XG | E26: 1 | F26: =E26*C26 -> 32.55
A27: =ROW()-4 -> 23 | B27: CAPA DE CHUVA PVC AMARELA G | C27: 40 | D27: G | E27: 14 | F27: =E27*C27 -> 560
A28: =ROW()-4 -> 24 | B28: CAPA DE CHUVA PVC AMARELA M | C28: 40 | D28: M | E28: 20 | F28: =E28*C28 -> 800
A29: =ROW()-4 -> 25 | B29: CAPA DE CHUVA PVC AMARELA P | C29: 40 | D29: P | E29: 20 | F29: =E29*C29 -> 800
A30: =ROW()-4 -> 26 | B30: CAPA DE CHUVA PVC AMARELA XG | C30: 40 | D30: GG | E30: 10 | F30: =E30*C30 -> 400
A31: =ROW()-4 -> 27 | B31: CAPACETE CLASSE B - ABA FRONTAL COM SUSPENSÃO E CATRACA | C31: ='ESTOQUE - SPO'!D36 -> 75 | D31: - | E31: 10 | F31: =E31*C31 -> 750
A32: =ROW()-4 -> 28 | B32: CARNEIRA + CATRACA | C32: 48.25 | D32: - | E32: 6 | F32: =E32*C32 -> 289.5
A33: =ROW()-4 -> 29 | B33: CHAVE DETECTORA DE TENSÃO | D33: - | E33: 15 | F33: =E33*C33 -> 0
A34: =ROW()-4 -> 30 | B34: CINTO DE SEGURANÇA MODELO PARAQUEDISTA TRABALHO EM ALTURA | C34: ='ESTOQUE - SPO'!D40 -> 584.2 | D34: - | E34: 20 | F34: =E34*C34 -> 11684
A35: =ROW()-4 -> 31 | B35: COLETE DE SINALIZAÇÃO REFLETIVO | C35: ='ESTOQUE - SPO'!D42 -> 21 | D35: - | E35: 34 | F35: =E35*C35 -> 714
A36: =ROW()-4 -> 32 | B36: CONE DE SINALIZAÇÃO | C36: ='ESTOQUE - SPO'!D43 -> 39 | D36: 50cm | E36: 50 | F36: =E36*C36 -> 1950
A37: =ROW()-4 -> 33 | B37: DISPOSITIVO GARRA MEIO DE VÃO | E37: 40
A38: =ROW()-4 -> 34 | B38: GARRAFA TÉRMICA 3,5 LITROS | C38: ='ESTOQUE - SPO'!D46 -> 28.94 | D38: - | E38: 25 | F38: =E38*C38 -> 723.5
A39: =ROW()-4 -> 35 | B39: GARRAFA TÉRMICA 5 LITROS | D39: - | E39: 0 | G39: REPOR ESTOQUE
A40: =ROW()-4 -> 36 | B40: JUGULAR TECIDO PARA CAPACETE 3M | C40: 8.63 | E40: 20 | F40: =E40*C40 -> 172.6
...

Sheet ESTOQUE SUL - SC
A1: Nome do Responsável Estoque - Tst ou Eng.: Bruno Odir Ramos
A2: Data da atualização da Planilha: 10/08/2026
A3: Estoque da Cidade/Base: São José/SC
A4: Nº | B4: DESCRIÇÃO | C4: R$ /item | D4: TAM. | E4: QTD | F4: R$ /estoque | G4: OBS.:
A5: 1 | B5: BALDE DE LONA | C5: ='ESTOQUE SUL - RS'!C5 -> 126.1 | E5: 43 | F5: =C5*E5 -> 5422.3
A6: 2 | B6: BANDEIROLA | E6: 33
A7: 3 | B7: BOLSA PARA KIT LVM | E7: 49
A8: 4 | B8: CALÇADO DE SEGURANÇA - TIPO BOTINA | C8: ='ESTOQUE SUL - RS'!C16 -> 104.29 | D8: 34 | E8: 0 | F8: =C8*E8 -> 0 | G8: REPOR ESTOQUE
A9: 5 | B9: CALÇADO DE SEGURANÇA - TIPO BOTINA | C9: ='ESTOQUE SUL - RS'!C17 -> 104.29 | D9: 35 | E9: 28 | F9: =C9*E9 -> 2920.12
A10: 6 | B10: CALÇADO DE SEGURANÇA - TIPO BOTINA | C10: ='ESTOQUE SUL - RS'!C18 -> 104.29 | D10: 36 | E10: 8 | F10: =C10*E10 -> 834.32
A11: 7 | B11: CALÇADO DE SEGURANÇA - TIPO BOTINA | C11: ='ESTOQUE SUL - RS'!C19 -> 104.29 | D11: 37 | E11: 21 | F11: =C11*E11 -> 2190.09
A12: 8 | B12: CALÇADO DE SEGURANÇA - TIPO BOTINA | C12: ='ESTOQUE SUL - RS'!C20 -> 104.29 | D12: 38 | E12: 22 | F12: =C12*E12 -> 2294.38
A13: 9 | B13: CALÇADO DE SEGURANÇA - TIPO BOTINA | C13: ='ESTOQUE SUL - RS'!C21 -> 104.29 | D13: 39 | E13: 26 | F13: =C13*E13 -> 2711.54
A14: 10 | B14: CALÇADO DE SEGURANÇA - TIPO BOTINA | C14: ='ESTOQUE SUL - RS'!C35 -> 21 | D14: 40 | E14: 20 | F14: =C14*E14 -> 420
A15: 11 | B15: CALÇADO DE SEGURANÇA - TIPO BOTINA | C15: ='ESTOQUE SUL - RS'!C35 -> 21 | D15: 41 | E15: 21 | F15: =C15*E15 -> 441
A16: 12 | B16: CALÇADO DE SEGURANÇA - TIPO BOTINA | C16: ='ESTOQUE SUL - RS'!C36 -> 39 | D16: 42 | E16: 36 | F16: =C16*E16 -> 1404
A17: 13 | B17: CALÇADO DE SEGURANÇA - TIPO BOTINA | C17: ='ESTOQUE SUL - RS'!C39 -> 0 | D17: 43 | E17: 21 | F17: =C17*E17 -> 0
A18: 14 | B18: CALÇADO DE SEGURANÇA - TIPO BOTINA | C18: ='ESTOQUE SUL - RS'!C43 -> 30.66 | D18: 44 | E18: 6 | F18: =C18*E18 -> 183.96
A19: 15 | B19: CALÇADO DE SEGURANÇA - TIPO BOTINA | C19: ='ESTOQUE SUL - RS'!C44 -> 30.66 | D19: 45 | E19: 8 | F19: =C19*E19 -> 245.28 | G19: REPOR ESTOQUE
A20: 16 | B20: CALÇADO DE SEGURANÇA - TIPO BOTINA | C20: ='ESTOQUE SUL - RS'!C47 -> 38 | D20: 46 | E20: 0 | F20: =C20*E20 -> 0
A21: 17 | B21: CAPA DE CHUVA PVC AMARELA | C21: ='ESTOQUE SUL - RS'!C27 -> 40 | D21: P | E21: 15 | F21: =C21*E21 -> 600 | G21: REPOR ESTOQUE
A22: 18 | B22: CAPA DE CHUVA PVC AMARELA | C22: ='ESTOQUE SUL - RS'!C28 -> 40 | D22: M | E22: 6 | F22: =C22*E22 -> 240 | G22: REPOR ESTOQUE
A23: 19 | B23: CAPA DE CHUVA PVC AMARELA | C23: ='ESTOQUE SUL - RS'!C29 -> 40 | D23: G | E23: 26 | F23: =C23*E23 -> 1040
A24: 20 | B24: CAPA DE CHUVA PVC AMARELA | C24: ='ESTOQUE SUL - RS'!C30 -> 40 | D24: GG | E24: 18 | F24: =C24*E24 -> 720 | G24: REPOR ESTOQUE
A25: 21 | B25: CAPACETE CLASSE B - ABA FRONTAL COM SUSPENSÃO E CATRACA | C25: ='ESTOQUE SUL - RS'!C26 -> 32.55 | E25: 27 | F25: =C25*E25 -> 878.85
A26: 22 | B26: CARNEIRA + CATRACA | C26: 48.25 | E26: 28 | F26: =C26*E26 -> 1351
A27: 23 | B27: CHAVE DETECTORA DE TENSÃO | C27: ='ESTOQUE SUL - RS'!C32 -> 48.25 | E27: 27 | F27: =C27*E27 -> 1302.75
A28: 24 | B28: CINTO DE SEGURANÇA MODELO PARAQUEDISTA TRABALHO EM ALTURA | C28: ='ESTOQUE SUL - RS'!C33 -> 0 | E28: 16 | F28: =C28*E28 -> 0
A29: 25 | B29: COLETE DE SINALIZAÇÃO REFLETIVO | C29: ='ESTOQUE SUL - RS'!C34 -> 584.2 | E29: 0 | F29: =C29*E29 -> 0 | G29: REPOR ESTOQUE
A30: 26 | B30: CONE DE SINALIZAÇÃO (75 cm) | C30: 111.82 | E30: 29 | F30: =C30*E30 -> 3242.78
A31: 27 | B31: GARRA MEIO DE VÃO | E31: 14
A32: 28 | B32: GARRAFA TÉRMICA | C32: ='ESTOQUE SUL - RS'!C36 -> 39 | E32: 24 | F32: =C32*E32 -> 936
A33: 29 | B33: JUGULAR TECIDO PARA CAPACETE 3M | C33: 8.63 | E33: 50 | F33: =C33*E33 -> 431.5
A34: 30 | B34: LUVA DE COBERTURA EM VAQUETA CANO LONGO | C34: 36.42 | E34: 0 | F34: =C34*E34 -> 0
A35: 31 | B35: LUVA DE SEGURANÇA PU ANTICORTE P | C35: 30.66 | E35: 7 | F35: =C35*E35 -> 214.62
A36: 32 | B36: LUVA DE SEGURANÇA PU ANTICORTE M | E36: 17
A37: 33 | B37: LUVA DE SEGURANÇA PU ANTICORTE G | E37: 12
A38: 34 | B38: LUVA DE SEGURANÇA PU ANTICORTE XG | E38: 45
A39: 35 | B39: LUVA DE VAQUETA CANO CURTO | C39: ='ESTOQUE SUL - RS'!C39 -> 0 | E39: 61 | F39: =C39*E39 -> 0
A40: 36 | B40: LUVA ISOLANTE - CLASSE 00 | C40: 383 | E40: 0 | F40: =C40*E40 -> 0
...

Sheet ESTOQUE - SPO
A1: Nome do Responsável Estoque (TST ou ENG): MÁRCIO CURY
A2: Responsáveis: CAIUBI (MÁRCIO)/ BARRA FUNDA (CÉSAR)/ R. PRETO (CÉSAR)/ CAMPINAS e PIRACICABA (PEDRO ROSSI)/ MOGI (ÉRIK)
A3: Estoque da Cidade ou Base: SÃO PAULO - SP
A4: Nº | B4: DESCRIÇÃO | C4: TAM. | D4: Valor do Item | E4: CAIUBI | F4: RIBEIRÃO PRETO | G4: BARRA FUNDA | H4: CAMPINAS | I4: PIRACICABA | J4: MOGI DAS CRUZES
A5: INVENTÁRIO REALIZADO EM: | E5: 13/08/2026 | F5: 22/07/2026 | G5: 46192 | H5: 46191 | J5: 22/06/2026
A6: 1 | B6: BALDE DE LONA | C6: UN | D6: 126.1 | E6: 269 | F6: 46 | G6: 41 | H6: 45 | I6: 8 | J6: 0
A7: 2 | B7: BANDEIROLA DE SINALIZAÇÃO SEM CABO | C7: UN | D7: 22.19 | E7: 99 | F7: 43 | G7: 183 | H7: 63 | I7: 14 | J7: 8
A8: 3 | B8: BOLSA PARA CORDA LVM | C8: UN | D8: 0 | E8: 26 | F8: 0 | G8: 0 | H8: 0 | I8: 0 | J8: 0
A9: 4 | B9: BOTINA DE PVC | C9: 38 | D9: 0 | E9: 8 | F9: 0 | G9: 0 | H9: 0 | I9: 0 | J9: 0
A10: 5 | B10: BOTINA DE PVC | C10: 39 | D10: 0 | E10: 17 | F10: 0 | G10: 0 | H10: 0 | I10: 0 | J10: 0
A11: 6 | B11: BOTINA DE PVC | C11: 40 | D11: 0 | E11: 2 | F11: 0 | G11: 0 | H11: 0 | I11: 0 | J11: 0
A12: 7 | B12: BOTINA DE PVC | C12: 41 | D12: 0 | E12: 5 | F12: 0 | G12: 0 | H12: 1 | I12: 0 | J12: 0
A13: 8 | B13: BOTINA DE PVC | C13: 42 | D13: 0 | E13: 6 | F13: 0 | G13: 0 | H13: 0 | I13: 0 | J13: 0
A14: 9 | B14: BOTINA DE PVC | C14: 43 | D14: 0 | E14: 4 | F14: 0 | G14: 0 | H14: 0 | I14: 0 | J14: 0
A15: 10 | B15: BOTINA DE PVC | C15: 44 | D15: 0 | E15: 2 | F15: 0 | G15: 0 | H15: 0 | I15: 0 | J15: 0
A16: 11 | B16: CALÇADO DE SEGURANÇA - TIPO BOTINA | C16: 33 | D16: 104.29 | E16: 37 | F16: 0 | G16: 0 | H16: 0 | I16: 0 | J16: 2
A17: 12 | B17: CALÇADO DE SEGURANÇA - TIPO BOTINA | C17: 34 | D17: 104.29 | E17: 36 | F17: 0 | G17: 0 | H17: 1 | I17: 0 | J17: 1
A18: 13 | B18: CALÇADO DE SEGURANÇA - TIPO BOTINA | C18: 35 | D18: 104.29 | E18: 37 | F18: 0 | G18: 5 | H18: 21 | I18: 0 | J18: 14
A19: 14 | B19: CALÇADO DE SEGURANÇA - TIPO BOTINA | C19: 36 | D19: 104.29 | E19: 21 | F19: 0 | G19: 2 | H19: 20 | I19: 1 | J19: 16
A20: 15 | B20: CALÇADO DE SEGURANÇA - TIPO BOTINA | C20: 37 | D20: 104.29 | E20: 20 | F20: 0 | G20: 5 | H20: 9 | I20: 3 | J20: 18
... A31: 26 | B31: CALÇADO DE SEGURANÇA - TIPO BOTINA | C31: 48 | D31: 104.29 | E31: 12 | F31: 0 | G31: 0 | H31: 0 | I31: 0 | J31: 0
A32: 27 | B32: CAPA DE CHUVA PVC AMARELA | C32: P | D32: 40 | E32: 126 | F32: 20 | G32: 4 | H32: 10 | I32: 0 | J32: 40
A33: 28 | B33: CAPA DE CHUVA PVC AMARELA | C33: M | D33: 40 | E33: 91 | F33: 19 | G33: 10 | H33: 1 | I33: 0 | J33: 27
A34: 29 | B34: CAPA DE CHUVA PVC AMARELA | C34: G | D34: 40 | E34: 92 | F34: 17 | G34: 23 | H34: 0 | I34: 2 | J34: 11
A35: 30 | B35: CAPA DE CHUVA PVC AMARELA | C35: XG | D35: 40 | E35: 166 | F35: 19 | G35: 5 | H35: 35 | I35: 2 | J35: 21
A36: 31 | B36: CAPACETE CLASSE B - ABA FRONTAL | C36: UN | D36: 75 | E36: 240 | F36: 30 | G36: 27 | H36: 8 | I36: 11 | J36: 33
A37: 32 | B37: CARNEIRA + CATRACA | C37: UN | D37: 48.25 | E37: 129 | F37: 20 | G37: 19 | H37: 38 | I37: 1 | J37: 20
A38: 33 | B38: CARTUCHO VO HONEYHELL RESPI | C38: UN | D38: 0 | E38: 54 | F38: 0 | G38: 0 | H38: 0 | I38: 0 | J38: 0
A39: 34 | B39: CHAVE DETECTORA DE TENSÃO | C39: UN | D39: 87.97 | E39: 64 | F39: 56 | G39: 74 | H39: 19 | I39: 0 | J39: 26
A40: 35 | B40: CINTO DE SEGURANÇA TRABALHO EM ALTURA | C40: UN | D40: 584.2 | E40: 292 | F40: 25 | G40: 27 | H40: 90 | I40: 6 | J40: 8
A41: 36 | B41: CINTO ERGONÔMICO | C41: UN | D41: 0 | E41: 12 | F41: 0 | G41: 0 | H41: 0 | I41: 0 | J41: 0
A42: 37 | B42: COLETE DE SINALIZAÇÃO REFLETIVO | C42: UN | D42: 21 | E42: 63 | F42: 15 | G42: 23 | H42: 16 | I42: 10 | J42: 11
A43: 38 | B43: CONE DE SINALIZAÇÃO (50 cm) | C43: UN | D43: 39 | E43: 740 | F43: 41 | G43: 86 | H43: 12 | I43: 12 | J43: 130
A44: 39 | B44: CONE DE SINALIZAÇÃO (75 cm) | C44: UN | D44: 0 | E44: 26 | F44: 0 | G44: 0 | H44: 0 | I44: 0 | J44: 0
A45: 40 | B45: DISPOSITIVO GARRA MEIO VÃO | C45: UN | E45: 70 | F45: 13 | G45: 44 | H45: 0 | I45: 0 | J45: 2
A46: 41 | B46: GARRAFA TÉRMICA 3,5 LITROS | C46: UN | D46: 28.94 | E46: 126 | F46: 0 | G46: 26 | H46: 3 | I46: 0 | J46: 11
A47: 42 | B47: GARRAFA TÉRMICA 5,0 LITROS | C47: UN | D47: 28.94 | E47: 16 | F47: 25 | G47: 2 | H47: 30 | I47: 8 | J47: 0
A48: 43 | B48: JUGULAR TECIDO PARA CAPACETE 3M | C48: UN | D48: 8.63 | E48: 40 | F48: 0 | G48: 38 | H48: 12 | I48: 0 | J48: 69
A49: 44 | B49: LUV ALTA TENSÃO CLASSE 00 TIPO II | C49: 9 | D49: 0 | E49: 7 | F49: 0 | G49: 0 | H49: 0 | I49: 0 | J49: 0
A50: 45 | B50: LUV ALTA TENSÃO CLASSE 00 TIPO II | C50: 10 | D50: 0 | E50: 7 | F50: 0 | G50: 0 | H50: 0 | I50: 0 | J50: 0
...

Sheet ESTOQUE SUL - PR
A1: Nome do Responsável Estoque - Tst ou Eng.: MAICON JOSE DE OLIVEIRA
A2: Data da atualização da Planilha: 03/07/2026
A3: Estoque da Cidade/Base: Curitiba - PR
A4: Nº | B4: DESCRIÇÃO | C4: R$ /item | D4: TAM. | E4: QTD | F4: R$ /estoque | G4: OBS.:
A5: 1 | B5: BALDE DE LONA | C5: ='ESTOQUE - SPO'!D6 -> 126.1 | D5: - | E5: 60 | F5: =C5*E5 -> 7566
A6: 2 | B6: CALÇADO DE SEGURANÇA - TIPO BOTINA | C6: ='ESTOQUE - SPO'!D16 -> 104.29 | D6: 33 | E6: 1 | F6: =C6*E6 -> 104.29
A7: 3 | B7: CALÇADO DE SEGURANÇA - TIPO BOTINA | C7: ='ESTOQUE - SPO'!D17 -> 104.29 | D7: 34 | E7: 3 | F7: =C7*E7 -> 312.87
A8: 4 | B8: CALÇADO DE SEGURANÇA - TIPO BOTINA | C8: ='ESTOQUE - SPO'!D18 -> 104.29 | D8: 35 | E8: 5 | F8: =C8*E8 -> 521.45
A9: 5 | B9: CALÇADO DE SEGURANÇA - TIPO BOTINA | C9: ='ESTOQUE - SPO'!D19 -> 104.29 | D9: 36 | E9: 5 | F9: =C9*E9 -> 521.45
A10: 6 | B10: CALÇADO DE SEGURANÇA - TIPO BOTINA | C10: ='ESTOQUE - SPO'!D20 -> 104.29 | D10: 37 | E10: 10 | F10: =C10*E10 -> 1042.9
A11: 7 | B11: CALÇADO DE SEGURANÇA - TIPO BOTINA | C11: ='ESTOQUE - SPO'!D21 -> 104.29 | D11: 38 | E11: 10 | F11: =C11*E11 -> 1042.9
A12: 8 | B12: CALÇADO DE SEGURANÇA - TIPO BOTINA | C12: ='ESTOQUE - SPO'!D22 -> 104.29 | D12: 39 | E12: 10 | F12: =C12*E12 -> 1042.9
A13: 9 | B13: CALÇADO DE SEGURANÇA - TIPO BOTINA | C13: ='ESTOQUE - SPO'!D23 -> 104.29 | D13: 40 | E13: 15 | F13: =C13*E13 -> 1564.35
A14: 10 | B14: CALÇADO DE SEGURANÇA - TIPO BOTINA | C14: ='ESTOQUE - SPO'!D24 -> 104.29 | D14: 41 | E14: 15 | F14: =C14*E14 -> 1564.35
A15: 11 | B15: CALÇADO DE SEGURANÇA - TIPO BOTINA | C15: ='ESTOQUE - SPO'!D25 -> 104.29 | D15: 42 | E15: 15 | F15: =C15*E15 -> 1564.35
A16: 12 | B16: CALÇADO DE SEGURANÇA - TIPO BOTINA | C16: ='ESTOQUE - SPO'!D26 -> 104.29 | D16: 43 | E16: 10 | F16: =C16*E16 -> 1042.9
A17: 13 | B17: CALÇADO DE SEGURANÇA - TIPO BOTINA | C17: ='ESTOQUE - SPO'!D27 -> 104.29 | D17: 44 | E17: 8 | F17: =C17*E17 -> 834.32
... A19: 15 | B19: CALÇADO DE SEGURANÇA - TIPO BOTINA | C19: ='ESTOQUE - SPO'!D29 -> 104.29 | D19: 46 | E19: 2 | F19: =C19*E19 -> 208.58
A20: 16 | B20: CAPA DE CHUVA PVC AMARELA | C20: ='ESTOQUE - SPO'!D32 -> 40 | D20: P | E20: 15 | F20: =C20*E20 -> 600
A21: 17 | B21: CAPA DE CHUVA PVC AMARELA | C21: ='ESTOQUE - SPO'!D33 -> 40 | D21: M | E21: 15 | F21: =C21*E21 -> 600
A22: 18 | B22: CAPA DE CHUVA PVC AMARELA | C22: ='ESTOQUE - SPO'!D34 -> 40 | D22: G | E22: 16 | F22: =C22*E22 -> 640
A23: 19 | B23: CAPA DE CHUVA PVC AMARELA | C23: ='ESTOQUE - SPO'!D35 -> 40 | D23: GG | E23: 15 | F23: =C23*E23 -> 600
A24: 20 | B24: CAPACETE CLASSE B - ABA FRONTAL COM SUSPENSÃO E CATRACA | C24: ='ESTOQUE - SPO'!D36 -> 75 | D24: - | E24: 25 | F24: =C24*E24 -> 1875
A25: 21 | B25: CARNEIRA DE TECIDO COM CATRACA | C25: ='ESTOQUE - SPO'!D37 -> 48.25 | D25: - | E25: 30 | F25: =C25*E25 -> 1447.5
A26: 22 | B26: CHAVE DETECTORA DE TENSÃO | D26: - | E26: 30 | F26: =C26*E26 -> 0
A27: 23 | B27: CINTO DE SEGURANÇA TRABALHO EM ALTURA | C27: ='ESTOQUE - SPO'!D40 -> 584.2 | D27: - | E27: 20 | F27: =C27*E27 -> 11684
A28: 24 | B28: COLETE DE SINALIZAÇÃO REFLETIVO | C28: ='ESTOQUE - SPO'!D42 -> 21 | D28: - | E28: 100 | F28: =C28*E28 -> 2100
A29: 25 | B29: CONE DE SINALIZAÇÃO (50 cm) | C29: ='ESTOQUE - SPO'!D43 -> 39 | D29: - | E29: 35 | F29: =C29*E29 -> 1365
A30: 26 | B30: GARRAFA TÉRMICA | C30: ='ESTOQUE - SPO'!D46 -> 28.94 | E30: 12 | F30: =C30*E30 -> 347.28
A31: 27 | B31: GARRA DE MEIO DE VÃO | E31: 15
A32: 28 | B32: JUGULAR PARA CAPACETE | C32: ='ESTOQUE - SPO'!D60 -> 0 | D32: - | E32: 35 | F32: =C32*E32 -> 0
A33: 29 | B33: LUVA DE SEGURANÇA PU ANTICORTE | C33: 30.66 | D33: P | E33: 200 | F33: =C32*E33 -> 0
A34: 30 | B34: LUVA DE SEGURANÇA PU ANTICORTE | C34: 30.66 | D34: M | E34: 150 | F34: =C32*E34 -> 0
A35: 31 | B35: LUVA DE SEGURANÇA PU ANTICORTE | C35: 30.66 | D35: G | E35: 180 | F35: =C32*E35 -> 0
A36: 32 | B36: LUVA DE SEGURANÇA PU ANTICORTE | C36: 30.66 | D36: XG | E36: 200 | F36: =C32*E36 -> 0
A37: 33 | B37: LUVA DE VAQUETA CANO CURTO | C37: ='ESTOQUE - SPO'!D55 -> 35.89 | E37: 120 | F37: =C37*E37 -> 4306.8
A38: 34 | B38: ÓCULOS DE SEGURANÇA - ESCURO | C38: ='ESTOQUE - SPO'!D71 -> 9 | D38: - | E38: 150 | F38: =C38*E38 -> 1350
A39: 35 | B39: ÓCULOS DE SEGURANÇA - INCOLOR | C39: ='ESTOQUE - SPO'!D70 -> 8.08 | D39: - | E39: 140 | F39: =C39*E39 -> 1131.2
A40: 36 | B40: ÓCULOS DE SEGURANÇA DE SOBREPOR | C40: ='ESTOQUE - SPO'!D73 -> 0 | D40: - | E40: 50 | F40: =C40*E40 -> 0
A41: 37 | B41: ÓCULOS DE SEGURANÇA DE SOBREPOR ESCURO | C41: ='ESTOQUE - SPO'!D73 -> 0 | D41: - | E41: 50 | F41: =C41*E41 -> 0
...

Sheet ESTOQUE SDT - RJ
A1: Nome do Responsável Estoque - Tst ou Eng.: Aline de Oliveira Rodrigues / Luis Carlos Neves Passeri
A2: Data da atualização da Planilha: 08/07/2026
A3: Estoque da Cidade/Base: Vila Isabel - Rio de Janeiro - RJ
A4: Nº | B4: DESCRIÇÃO | C4: R$ /item | D4: TAM. | E4: QTD | F4: R$ /estoque | G4: OBS.:
A5: 1 | B5: ÁLCOOL GEL | D5: - | E5: 0 | F5: =C5*E5 -> 0
A6: 2 | B6: BALDE DE LONA | C6: ='ESTOQUE - SPO'!D6 -> 126.1 | D6: - | E6: 0 | F6: =C6*E6 -> 0
A7: =ROW()-4 -> 3 | B7: BANDEROLA PARA ESCADA | D7: - | E7: 190 | F7: =C7*E7 -> 0
A8: 4 | B8: BOTA PVC LONGA 32 CM Nº 38 | C8: 69.9 | D8: 38 | E8: 0 | F8: =C8*E8 -> 0
A9: 5 | B9: BOTA PVC LONGA 32 CM Nº 39 | C9: 69.9 | D9: 39 | E9: 0 | F9: =C9*E9 -> 0
A10: 6 | B10: BOTA PVC LONGA 32 CM Nº 40 | C10: 69.9 | D10: 40 | E10: 0 | F10: =C10*E10 -> 0
A11: 7 | B11: BOTA PVC LONGA 32 CM Nº 41 | C11: 69.9 | D11: 41 | E11: 0 | F11: =C11*E11 -> 0
A12: 8 | B12: BOTA PVC LONGA 32 CM Nº 42 | C12: 69.9 | D12: 42 | E12: 0 | F12: =C12*E12 -> 0
A13: 9 | B13: BOTINA DE SEGURANCA SEM BIQUEIRA (VICHI) Nº 33 | C13: 104.29 | D13: 33 | E13: 7 | F13: =C13*E13 -> 730.03
A14: 10 | B14: BOTINA DE SEGURANCA SEM BIQUEIRA (VICHI) Nº 34 | C14: 104.29 | D14: 32 | E14: 7 | F14: =C14*E14 -> 730.03
A15: 11 | B15: BOTINA DE SEGURANCA SEM BIQUEIRA (VICHI) Nº 35 | C15: 104.29 | D15: 35 | E15: 0 | F15: =C15*E15 -> 0
A16: 12 | B16: BOTINA DE SEGURANCA SEM BIQUEIRA (VICHI) Nº 36 | C16: 104.29 | D16: 36 | E16: 0 | F16: =C16*E16 -> 0
A17: 13 | B17: BOTINA DE SEGURANCA SEM BIQUEIRA (VICHI) Nº 37 | C17: 104.29 | D17: 37 | E17: 1 | F17: =C17*E17 -> 104.29
A18: 15 | B18: BOTINA DE SEGURANCA SEM BIQUEIRA (VICHI) Nº 38 | C18: 104.29 | D18: 38 | E18: 1 | F18: =C18*E18 -> 104.29
A19: 16 | B19: BOTINA DE SEGURANCA SEM BIQUEIRA (VICHI) Nº 39 | C19: 104.29 | D19: 39 | E19: 6 | F19: =C19*E19 -> 625.74
... A27: 24 | B27: BOTINA DE SEGURANCA SEM BIQUEIRA (VICHI) Nº 48 | C27: 104.29 | D27: 48 | E27: 0 | F27: =C27*E27 -> 0
A28: 25 | B28: CAPA DE CHUVA COM CAPUZ AMARELA | C28: 40 | E28: 172 | F28: =C28*E28 -> 6880
A29: 26 | B29: CAPACETE ALPINISTA SEM ABA | C29: 180.93 | D29: - | E29: 29 | F29: =C29*E29 -> 5246.97
A30: 27 | B30: CAPACETE CLASSE B - ABA FRONTAL | C30: 75 | D30: - | E30: 173 | F30: =C30*E30 -> 12975
A31: 28 | B31: CARNEIRA + CATRACA PARA CAPACETE | C31: 48.25 | D31: - | E31: 46 | F31: =C31*E31 -> 2219.5
A32: 29 | B32: CHAVE DETECTORA DE TENSÃO | C32: 87.97 | D32: - | E32: 192 | F32: =C32*E32 -> 16890.24
A33: 30 | B33: CINTO DE SEGURANÇA - TELECOM | C33: 584.2 | D33: - | E33: 21 | F33: =C33*E33 -> 12268.2
A34: 31 | B34: COLETE DE SINALIZAÇÃO | C34: 21 | D34: - | E34: 7 | F34: =C34*E34 -> 147
A35: 32 | B35: CONE DE SINALIZAÇÃO BORRACHA, LARANJA/BRANCO, 50 CM | C35: 39 | D35: - | E35: 17 | F35: =C35*E35 -> 663
A36: 33 | B36: FITA DE ANCORAGEM AMARELA | C36: 81.83 | D36: - | E36: 61 | F36: =C36*E36 -> 4991.63
A37: 34 | B37: GARRA MEIO DE VÃO | E37: 208
A38: 35 | B38: GARRAFA TÉRMICA – 3,5 | C38: 28.94 | D38: - | E38: 109 | F38: =C38*E38 -> 3154.46
A39: 36 | B39: JUGULAR TECIDO CAPACETE 3M | C39: 8.63 | D39: - | E39: 2 | F39: =C39*E39 -> 17.26
A40: 37 | B40: LUVA ISOLANTE - CLASSE 00 – 500 V | C40: 267.69 | E40: 0 | F40: =C40*E40 -> 0
A41: 38 | B41: LUVA DE COBERTURA EM VAQUETA CANO LONGO | C41: 267.69 | E41: 0 | F41: =C41*E41 -> 0
A42: 39 | B42: LUVA DE PVC CANO CURTO VERDE | C42: 9.8 | E42: 100 | F42: =C43*E42 -> 3066
A43: 40 | B43: LUVA DE SEGURANÇA PU ANTICORTE | C43: 30.66 | E43: 241 | F43: =C44*E43 -> 9158
A44: 41 | B44: LUVA DE VAQUETA CANO CURTO | C44: 38 | E44: 50 | F44: =C44*E44 -> 1900
A45: 42 | B45: LUVA DE VAQUETA CONFORT SEM DEDO | C45: 36.31 | E45: 29 | F45: =C45*E45 -> 1052.99
A46: 43 | B46: LUVA PIGMENTADA | C46: 23.7 | E46: 35
A47: 44 | B47: MÁSCARA DE PANO - ROXA VIVO (pacote com 5) | D47: - | E47: 198 | F47: =C47*E47 -> 0
...

Sheet ESTOQUE SDT-MG
A1: Nome do Responsável Estoque - Tst ou Eng.: Willander Ramos dos Reiss
A2: Data da atualização da Planilha: 21/08/2026
A3: Estoque da Cidade/Base: Barão Homem de Melo - Belo Horizonte - MG
A4: Nº | B4: DESCRIÇÃO | C4: R$ /item | D4: TAM. | E4: QTD | F4: R$ /estoque | G4: OBS.:
A5: 1 | B5: ÁLCOOL GEL | D5: - | E5: 0 | F5: =C5*E5 -> 0
A6: 2 | B6: BALDE DE LONA | C6: 126.1 | D6: - | E6: 56 | F6: =C6*E6 -> 7061.6
A7: 3 | B7: BOTINA DE SEGURANCA SEM BIQUEIRA (VICHI) Nº 33 | C7: 104.29 | D7: 33 | E7: 1 | F7: =C7*E7 -> 104.29
A8: 4 | B8: BOTINA DE SEGURANCA SEM BIQUEIRA (VICHI) Nº 34 | C8: 104.29 | D8: 34 | E8: 1 | F8: =C8*E8 -> 104.29
A9: 5 | B9: BOTINA DE SEGURANCA SEM BIQUEIRA (VICHI) Nº 35 | C9: 104.29 | D9: 35 | E9: 8 | F9: =C9*E9 -> 834.32
A10: 6 | B10: BOTINA DE SEGURANCA SEM BIQUEIRA (VICHI) Nº 36 | C10: 104.29 | D10: 36 | E10: 2 | F10: =C10*E10 -> 208.58
A11: 7 | B11: BOTINA DE SEGURANCA SEM BIQUEIRA (VICHI) Nº 37 | C11: 104.29 | D11: 37 | E11: 0 | F11: =C11*E11 -> 0
A12: 8 | B12: BOTINA DE SEGURANCA SEM BIQUEIRA (VICHI) Nº 38 | C12: 104.29 | D12: 38 | E12: 0 | F12: =C12*E12 -> 0
A13: 9 | B13: BOTINA DE SEGURANCA SEM BIQUEIRA (VICHI) Nº 39 | C13: 104.29 | D13: 39 | E13: 3 | F13: =C13*E13 -> 312.87
A14: 10 | B14: BOTINA DE SEGURANCA SEM BIQUEIRA (VICHI) Nº 40 | C14: 104.29 | D14: 40 | E14: 2 | F14: =C14*E14 -> 208.58
A15: 11 | B15: BOTINA DE SEGURANCA SEM BIQUEIRA (VICHI) Nº 41 | C15: 104.29 | D15: 41 | E15: 0 | F15: =C15*E15 -> 0
A16: 12 | B16: BOTINA DE SEGURANCA SEM BIQUEIRA (VICHI) Nº 42 | C16: 104.29 | D16: 42 | E16: 4 | F16: =C16*E16 -> 417.16
A17: 13 | B17: BOTINA DE SEGURANCA SEM BIQUEIRA (VICHI) Nº 43 | C17: 104.29 | D17: 43 | E17: 8 | F17: =C17*E17 -> 834.32
A18: 14 | B18: BOTINA DE SEGURANCA SEM BIQUEIRA (VICHI) Nº 44 | C18: 104.29 | D18: 44 | E18: 4 | F18: =C18*E18 -> 417.16
... A21: 17 | B21: BOTINA DE SEGURANCA SEM BIQUEIRA (VICHI) Nº 48 | C21: 104.29 | D21: 48 | E21: 0 | F21: =C21*E21 -> 0
B22: CAPA DE CHUVA COM CAPUZ AMARELA - M | C22: 40 | E22: 19 | F22: =C22*E22 -> 760
B23: CAPA DE CHUVA COM CAPUZ AMARELA - G | C23: 40 | E23: 1 | F23: =C23*E23 -> 40
B24: CAPA DE CHUVA COM CAPUZ AMARELA - EXG | C24: 40 | D24: - | E24: 22 | F24: =C24*E24 -> 880
B25: CAPACETE ALPINISTA SEM ABA | C25: 180.23 | D25: - | E25: 0 | F25: =C25*E25 -> 0
B26: CAPACETE CLASSE B - ABA FRONTAL | C26: 75 | D26: - | E26: 64 | F26: =C26*E26 -> 4800
B27: CARNEIRA + CATRACA PARA CAPACETE | C27: 48.25 | D27: - | E27: 99 | F27: =C27*E27 -> 4776.75
B28: CHAVE DETECTORA DE TENSÃO | C28: 87.97 | D28: - | E28: 72 | F28: =C28*E28 -> 6333.84
B29: CINTO DE SEGURANÇA - TELECOM | C29: 584.2 | D29: - | E29: 63 | F29: =C29*E29 -> 36804.6
B30: COLETE DE SINALIZAÇÃO | C30: 21 | D30: - | E30: 38 | F30: =C30*E30 -> 798
B31: CONE DE SINALIZAÇÃO BORRACHA, LARANJA/BRANCO, 50 CM | C31: 39 | D31: - | E31: 182 | F31: =C31*E31 -> 7098
B32: GARRA MEIO DE VÃO | E32: 46
B33: GARRAFA TÉRMICA – 3,5 | C33: 28.94 | D33: - | E33: 59 | F33: =C33*E33 -> 1707.46
B34: JUGULAR TECIDO PARA CAPACETE 3M | C34: 8.63 | D34: - | E34: 88 | F34: =C34*E34 -> 759.44
B35: KIT PRIMEIROS SOCORROS | D35: - | E35: 0 | F35: =C35*E35 -> 0
B36: LUVA ISOLANTE - CLASSE 00 – 500 V | C36: 267.69 | D36: - | E36: 0 | F36: =C36*E36 -> 0
B37: LUVA DE COBERTURA EM VAQUETA CANO LONGO | C37: 36.42 | D37: - | E37: 0 | F37: =C37*E37 -> 0
B38: LUVA DE SEGURANÇA PU ANTICORTE - 7 | C38: 30.66 | E38: 76 | F38: =C38*E38 -> 2330.16
B39: LUVA DE SEGURANÇA PU ANTICORTE - 8 | C39: 30.66 | E39: 0 | F39: =C39*E39 -> 0
B40: LUVA DE SEGURANÇA PU ANTICORTE - 9 | C40: 30.66 | E40: 10 | F40: =C40*E40 -> 306.6
B41: LUVA DE SEGURANÇA PU ANTICORTE - 10 | C41: 30.66 | E41: 15 | F41: =C41*E41 -> 459.9
B42: LUVA DE VAQUETA CANO CURTO 9 | C42: 38 | D42: - | E42: 13 | F42: =C42*E42 -> 494
...

Sheet ESTOQUE SDT - ES
A1: Nome do Responsável Estoque - Tst ou Eng.: Karine Novaes Assem
A2: Data da atualização da Planilha: 24/04/2026
A3: Estoque da Cidade/Base: Mata da Praia - Vitória – ES - Av. Adalberto Simão Nader, 531 - CEP: 29066-900
A4: Nº | B4: DESCRIÇÃO | C4: R$ /item | D4: TAM. | E4: QTD | F4: R$ /estoque | G4: OBS.:
A5: 1 | B5: ÁlCOOL GEL 500ML | D5: - | E5: 0 | F5: =C5*E5 -> 0
A6: 2 | B6: BALDE DE LONA | C6: 126.1 | D6: - | E6: 107 | F6: =C6*E6 -> 13492.7
A7: 3 | B7: BOTA PVC LONGA 32 CM Nº 38 | C7: 69.9 | D7: 38 | E7: 0 | F7: =C7*E7 -> 0
A8: 4 | B8: BOTA PVC LONGA 32 CM Nº 39 | D8: 39 | E8: 0
A9: 5 | B9: BOTA PVC LONGA 32 CM Nº 40 | D9: 40 | E9: 0
A10: 6 | B10: BOTA PVC LONGA 32 CM Nº 41 | D10: 41 | E10: 0
A11: 7 | B11: BOTA PVC LONGA 32 CM Nº 42 | D11: 42 | E11: 0
A12: 8 | B12: BOTINA DE SEGURANCA SEM BIQUEIRA (VICHI) Nº 33 | C12: 104.29 | D12: 33 | E12: 0 | F12: =C12*E12 -> 0
A13: 9 | B13: BOTINA DE SEGURANCA SEM BIQUEIRA (VICHI) Nº 34 | C13: 104.29 | D13: 34 | E13: 1 | F13: =C13*E13 -> 104.29
A14: 10 | B14: BOTINA DE SEGURANCA SEM BIQUEIRA (VICHI) Nº 35 | C14: 104.29 | D14: 35 | E14: 0 | F14: =C14*E14 -> 0
A15: 11 | B15: BOTINA DE SEGURANCA SEM BIQUEIRA (VICHI) Nº 36 | C15: 104.29 | D15: 36 | E15: 0 | F15: =C15*E15 -> 0
A16: 12 | B16: BOTINA DE SEGURANCA SEM BIQUEIRA (VICHI) Nº 37 | C16: 104.29 | D16: 37 | E16: 11 | F16: =C16*E16 -> 1147.19
A17: 13 | B17: BOTINA DE SEGURANCA SEM BIQUEIRA (VICHI) Nº 38 | C17: 104.29 | D17: 38 | E17: 10 | F17: =C17*E17 -> 1042.9
A18: 14 | B18: BOTINA DE SEGURANCA SEM BIQUEIRA (VICHI) Nº 39 | C18: 104.29 | D18: 39 | E18: 13 | F18: =C18*E18 -> 1355.77
A19: 15 | B19: BOTINA DE SEGURANCA SEM BIQUEIRA (VICHI) Nº 40 | C19: 104.29 | D19: 40 | E19: 22 | F19: =C19*E19 -> 2294.38
A20: 16 | B20: BOTINA DE SEGURANCA SEM BIQUEIRA (VICHI) Nº 41 | C20: 104.29 | D20: 41 | E20: 17 | F20: =C20*E20 -> 1772.93
A21: 17 | B21: BOTINA DE SEGURANCA SEM BIQUEIRA (VICHI) Nº 42 | C21: 104.29 | D21: 42 | E21: 20 | F21: =C21*E21 -> 2085.8
A22: 18 | B22: BOTINA DE SEGURANCA SEM BIQUEIRA (VICHI) Nº 43 | C22: 104.29 | D22: 43 | E22: 20 | F22: =C22*E22 -> 2085.8
A23: 19 | B23: BOTINA DE SEGURANCA SEM BIQUEIRA (VICHI) Nº 44 | C23: 104.29 | D23: 44 | E23: 18 | F23: =C23*E23 -> 1877.22
... A26: 22 | B26: BOTINA DE SEGURANCA SEM BIQUEIRA (VICHI) Nº 48 | C26: 104.29 | D26: 48 | E26: 0 | F26: =C26*E26 -> 0
A27: 23 | B27: CAPA DE CHUVA COM CAPUZ AMARELA | C27: 40 | D27: M/G | E27: 111 | F27: =C27*E27 -> 4440
A28: 24 | B28: CAPACETE ALPINISTA SEM ABA | C28: 180.23 | D28: - | E28: 0 | F28: =C28*E28 -> 0
A29: 25 | B29: CAPACETE CLASSE B - ABA FRONTAL | C29: 75 | D29: - | E29: 101 | F29: =C29*E29 -> 7575
A30: 26 | B30: CARNEIRA + CATRACA PARA CAPACETE 3M | C30: 48.25 | E30: 0 | F30: =C30*E30 -> 0
A31: 27 | B31: CHAVE TESTE POR INDUÇÃO | E31: 116
A32: 28 | B32: CINTO DE SEGURANÇA - TELECOM | C32: 584.2 | D32: tam 1 | E32: 108 | F32: =C32*E32 -> 63093.6
A33: 29 | B33: COLETE DE SINALIZAÇÃO | C33: 21 | D33: - | E33: 115 | F33: =C33*E33 -> 2415
A34: 30 | B34: CONE DE SINALIZAÇÃO BORRACHA, LARANJA/BRANCO, 50 CM | C34: 39 | D34: - | E34: 412 | F34: =C34*E34 -> 16068
A35: 31 | B35: GARRAFA TÉRMICA | C35: 28.94 | D35: 5 Litros | E35: 105 | F35: =C35*E35 -> 3038.7
A36: 32 | B36: GARRA MEIO DE VÃO | E36: 116
A37: 33 | B37: JUGULAR TECIDO PARA CAPACETE | C37: 8.63 | E37: 21 | F37: =C37*E37 -> 181.23
A38: 34 | B38: LUVA ISOLANTE - CLASSE 00 – 500 V | C38: 267.69 | D38: - | E38: 0 | F38: =C38*E38 -> 0
A39: 35 | B39: LUVA DE COBERTURA EM VAQUETA CANO LONGO | C39: 267.69 | D39: - | E39: 0 | F39: =C39*E39 -> 0
A40: 36 | B40: LUVA DE SEGURANÇA PU ANTICORTE | C40: 30.66 | E40: 165 | F40: =C40*E40 -> 5058.9
A41: 37 | B41: LUVA DE VAQUETA CANO CURTO | C41: 38 | D41: M/G | E41: 180 | F41: =C41*E41 -> 6840
A42: 38 | B42: LUVA DE VAQUETA SEM DEDO | C42: 36.31 | D42: - | E42: 0 | F42: =C42*E42 -> 0
...

Sheet ESTOQUE CWN - DF
A1: Nome do Responsável Estoque - Tst ou Eng.: Luana
A2: Data da atualização da Planilha: 15/06/2026
A3: Estoque da Cidade/Base: Brasília-DF
A4: Nº | B4: DESCRIÇÃO | C4: R$ /item | D4: TAM. | E4: QTD | F4: R$ /estoque | G4: OBS.:
A5: 1 | B5: ÁLCOOL GEL | D5: - | E5: 0 | F5: =C5*E5 -> 0
A6: 2 | B6: BALDE DE LONA | C6: ='ESTOQUE - SPO'!D6 -> 126.1 | D6: - | E6: 2 | F6: =C6*E6 -> 252.2
A7: 3 | B7: BOTA PVC LONGA 32 CM Nº 38 | C7: 69.9 | D7: 38 | E7: 0 | F7: =C7*E7 -> 0
A8: 4 | B8: BOTA PVC LONGA 32 CM Nº 39 | C8: 69.9 | D8: 39 | E8: 0 | F8: =C8*E8 -> 0
A9: 5 | B9: BOTA PVC LONGA 32 CM Nº 40 | C9: 69.9 | D9: 40 | E9: 0 | F9: =C9*E9 -> 0
A10: 6 | B10: BOTA PVC LONGA 32 CM Nº 41 | C10: 69.9 | D10: 41 | E10: 0 | F10: =C10*E10 -> 0
A11: 7 | B11: BOTA PVC LONGA 32 CM Nº 42 | C11: 69.9 | D11: 42 | E11: 0 | F11: =C11*E11 -> 0
A12: 8 | B12: BOTINA DE SEGURANCA SEM BIQUEIRA (VICHI) Nº 33 | C12: 104.29 | D12: 33 | E12: 0 | F12: =C12*E12 -> 0
A13: 9 | B13: BOTINA DE SEGURANCA SEM BIQUEIRA (VICHI) Nº 34 | C13: 104.29 | D13: 32 | E13: 0 | F13: =C13*E13 -> 0
A14: 10 | B14: BOTINA DE SEGURANCA SEM BIQUEIRA (VICHI) Nº 35 | C14: 104.29 | D14: 35 | E14: 5 | F14: =C14*E14 -> 521.45
A15: 11 | B15: BOTINA DE SEGURANCA SEM BIQUEIRA (VICHI) Nº 36 | C15: 104.29 | D15: 36 | E15: 1 | F15: =C15*E15 -> 104.29
A16: 12 | B16: BOTINA DE SEGURANCA SEM BIQUEIRA (VICHI) Nº 37 | C16: 104.29 | D16: 37 | E16: 10 | F16: =C16*E16 -> 1042.9
A17: 13 | B17: BOTINA DE SEGURANCA SEM BIQUEIRA (VICHI) Nº 38 | C17: 104.29 | D17: 38 | E17: 14 | F17: =C17*E17 -> 1460.06
A18: 14 | B18: BOTINA DE SEGURANCA SEM BIQUEIRA (VICHI) Nº 39 | C18: 104.29 | D18: 39 | E18: 20 | F18: =C18*E18 -> 2085.8
... A26: 22 | B26: BOTINA DE SEGURANCA SEM BIQUEIRA (VICHI) Nº 48 | C26: 104.29 | D26: 48 | E26: 0 | F26: =C26*E26 -> 0
A27: 23 | B27: CAPA DE CHUVA COM CAPUZ AMARELA | C27: 40 | E27: 39 | F27: =C27*E27 -> 1560
A28: 24 | B28: CAPACETE ALPINISTA SEM ABA | C28: 180.93 | D28: - | E28: 0 | F28: =C28*E28 -> 0
A29: 25 | B29: CAPACETE CLASSE B - ABA FRONTAL | C29: 75 | D29: - | E29: 9 | F29: =C29*E29 -> 675
A30: 26 | B30: CARNEIRA + CATRACA PARA CAPACETE | C30: 48.25 | D30: - | E30: 53 | F30: =C30*E30 -> 2557.25
A31: 27 | B31: CHAVE DETECTORA DE TENSÃO | C31: 87.97 | D31: - | E31: 28 | F31: =C31*E31 -> 2463.16
A32: 28 | B32: CINTO DE SEGURANÇA - TELECOM | C32: 584.2 | D32: - | E32: 11 | F32: =C32*E32 -> 6426.2
A33: 29 | B33: COLETE DE SINALIZAÇÃO | C33: 21 | D33: - | E33: 4 | F33: =C33*E33 -> 84
A34: 30 | B34: CONE DE SINALIZAÇÃO BORRACHA, LARANJA/BRANCO, 50 CM | C34: 39 | D34: - | E34: 18 | F34: =C34*E34 -> 702
A35: 31 | B35: FITA DE ANCORAGEM AMARELA | C35: 81.83 | D35: - | E35: 0 | F35: =C35*E35 -> 0
A36: 32 | B36: GARRAFA TÉRMICA – 3,5 | C36: 28.94 | D36: - | E36: 23 | F36: =C36*E36 -> 665.62
A37: 33 | B37: JUGULAR TECIDO CAPACETE 3M | C37: 8.63 | D37: - | E37: 29 | F37: =C37*E37 -> 250.27
A38: 34 | B38: LUVA DE SEGURANÇA PU ANTICORTE P | C38: 267.69 | E38: 12 | F38: =C38*E38 -> 3212.28
A39: 35 | B39: LUVA DE SEGURANÇA PU ANTICORTE M | C39: 267.69 | E39: 0 | F39: =C39*E39 -> 0
A40: 36 | B40: LUVA DE SEGURANÇA PU ANTICORTE G | C40: 9.8 | E40: 0 | F40: =C41*E40 -> 0
A41: 37 | B41: LUVA DE SEGURANÇA PU ANTICORTE XG | C41: 30.66 | E41: 0 | F41: =C42*E41 -> 0
A42: 38 | B42: LUVA DE VAQUETA CANO CURTO | C42: 38 | E42: 38 | F42: =C42*E42 -> 1444
A43: 39 | B43: LUVA DE VAQUETA CONFORT SEM DEDO | C43: 36.31 | E43: 0 | F43: =C43*E43 -> 0
A44: 40 | B44: LUVA PIGMENTADA | C44: 23.7 | E44: 0
A45: 41 | B45: MÁSCARA DE PANO - ROXA VIVO (pacote com 5) | D45: - | E45: 0 | F45: =C45*E45 -> 0
A46: 42 | B46: MOSQUETÃO OVAL AÇO TRAVA ROSCA | C46: 62.14 | D46: - | E46: 0 | F46: =C46*E46 -> 0
A47: 43 | B47: ÓCULOS DE SEGURANÇA - FUMÊ | C47: 4 | E47: 0 | F47: =C47*E47 -> 0
...

Sheet ESTOQUE CWN- PA
A1: Nome do Responsável Estoque - Tst ou Eng.: Luana
A2: Data da atualização da Planilha:16/06/2026
A3: Estoque da Cidade/Base: Brasília-DF
A4: Nº | B4: DESCRIÇÃO | C4: R$ /item | D4: TAM. | E4: QTD | F4: R$ /estoque | G4: OBS.:
A5: 1 | B5: ÁLCOOL GEL | D5: - | E5: 0 | F5: =C5*E5 -> 0
A6: 2 | B6: BALDE DE LONA | C6: ='ESTOQUE - SPO'!D6 -> 126.1 | D6: - | E6: 25 | F6: =C6*E6 -> 3152.5
A7: 3 | B7: BOTA PVC LONGA 32 CM Nº 38 | C7: 69.9 | D7: 38 | E7: 0 | F7: =C7*E7 -> 0
A8: 4 | B8: BOTA PVC LONGA 32 CM Nº 39 | C8: 69.9 | D8: 39 | E8: 0 | F8: =C8*E8 -> 0
A9: 5 | B9: BOTA PVC LONGA 32 CM Nº 40 | C9: 69.9 | D9: 40 | E9: 0 | F9: =C9*E9 -> 0
A10: 6 | B10: BOTA PVC LONGA 32 CM Nº 41 | C10: 69.9 | D10: 41 | E10: 0 | F10: =C10*E10 -> 0
A11: 7 | B11: BOTA PVC LONGA 32 CM Nº 42 | C11: 69.9 | D11: 42 | E11: 0 | F11: =C11*E11 -> 0
A12: 8 | B12: BOTINA DE SEGURANCA SEM BIQUEIRA (VICHI) Nº 33 | C12: 104.29 | D12: 33 | E12: 0 | F12: =C12*E12 -> 0
A13: 9 | B13: BOTINA DE SEGURANCA SEM BIQUEIRA (VICHI) Nº 34 | C13: 104.29 | D13: 32 | E13: 0 | F13: =C13*E13 -> 0
A14: 10 | B14: BOTINA DE SEGURANCA SEM BIQUEIRA (VICHI) Nº 35 | C14: 104.29 | D14: 35 | E14: 0 | F14: =C14*E14 -> 0
A15: 11 | B15: BOTINA DE SEGURANCA SEM BIQUEIRA (VICHI) Nº 36 | C15: 104.29 | D15: 36 | E15: 5 | F15: =C15*E15 -> 521.45
A16: 12 | B16: BOTINA DE SEGURANCA SEM BIQUEIRA (VICHI) Nº 37 | C16: 104.29 | D16: 37 | E16: 10 | F16: =C16*E16 -> 1042.9
A17: 13 | B17: BOTINA DE SEGURANCA SEM BIQUEIRA (VICHI) Nº 38 | C17: 104.29 | D17: 38 | E17: 10 | F17: =C17*E17 -> 1042.9
A18: 14 | B18: BOTINA DE SEGURANCA SEM BIQUEIRA (VICHI) Nº 39 | C18: 104.29 | D18: 39 | E18: 11 | F18: =C18*E18 -> 1147.19
... A26: 22 | B26: BOTINA DE SEGURANCA SEM BIQUEIRA (VICHI) Nº 48 | C26: 104.29 | D26: 48 | E26: 0 | F26: =C26*E26 -> 0
A27: 23 | B27: CAPA DE CHUVA COM CAPUZ AMARELA | C27: 40 | E27: 12 | F27: =C27*E27 -> 480
A28: 24 | B28: CAPACETE ALPINISTA SEM ABA | C28: 180.93 | D28: - | E28: 0 | F28: =C28*E28 -> 0
A29: 25 | B29: CAPACETE CLASSE B - ABA FRONTAL | C29: 75 | D29: - | E29: 15 | F29: =C29*E29 -> 1125
A30: 26 | B30: CARNEIRA + CATRACA PARA CAPACETE | C30: 48.25 | D30: - | E30: 50 | F30: =C30*E30 -> 2412.5
A31: 27 | B31: CHAVE DETECTORA DE TENSÃO | C31: 87.97 | D31: - | E31: 30 | F31: =C31*E31 -> 2639.1
A32: 28 | B32: CINTO DE SEGURANÇA - TELECOM | C32: 584.2 | D32: - | E32: 20 | F32: =C32*E32 -> 11684
A33: 29 | B33: COLETE DE SINALIZAÇÃO | C33: 21 | D33: - | E33: 33 | F33: =C33*E33 -> 693
A34: 30 | B34: CONE DE SINALIZAÇÃO BORRACHA, LARANJA/BRANCO, 50 CM | C34: 39 | D34: - | E34: 10 | F34: =C34*E34 -> 390
A35: 31 | B35: FITA DE ANCORAGEM AMARELA | C35: 81.83 | D35: - | E35: 0 | F35: =C35*E35 -> 0
A36: 32 | B36: GARRAFA TÉRMICA – 3,5 | C36: 28.94 | D36: - | E36: 50 | F36: =C36*E36 -> 1447
A37: 33 | B37: JUGULAR TECIDO CAPACETE 3M | C37: 8.63 | D37: - | E37: 30 | F37: =C37*E37 -> 258.9
A38: 34 | B38: LUVA DE PVC CANO CURTO VERDE P | C38: 267.69 | E38: 0 | F38: =C38*E38 -> 0
A39: 35 | B39: LUVA DE PVC CANO CURTO VERDE M | C39: 267.69 | E39: 0 | F39: =C39*E39 -> 0
A40: 36 | B40: LUVA DE PVC CANO CURTO VERDE G | C40: 9.8 | E40: 0 | F40: =C41*E40 -> 0
A41: 37 | B41: LUVA DE SEGURANÇA PU ANTICORTE XG | C41: 30.66 | E41: 19 | F41: =C42*E41 -> 722
A42: 38 | B42: LUVA DE VAQUETA CANO CURTO | C42: 38 | E42: 23 | F42: =C42*E42 -> 874
A43: 39 | B43: LUVA DE VAQUETA CONFORT SEM DEDO | C43: 36.31 | E43: 0 | F43: =C43*E43 -> 0
A44: 40 | B44: LUVA PIGMENTADA | C44: 23.7 | E44: 0
A45: 41 | B45: MÁSCARA DE PANO - ROXA VIVO (pacote com 5) | D45: - | E45: 0 | F45: =C45*E45 -> 0
A46: 42 | B46: MOSQUETÃO OVAL AÇO TRAVA ROSCA | C46: 62.14 | D46: - | E46: 0 | F46: =C46*E46 -> 0
A47: 43 | B47: ÓCULOS DE SEGURANÇA - FUMÊ | C47: 4 | E47: 35 | F47: =C47*E47 -> 140
...

Sheet ESTOQUE CWN - AM
A1: Nome do Responsável Estoque - Tst ou Eng.: Luana
A2: Data da atualização da Planilha:
A3: Estoque da Cidade/Base: Manaus - AM
A4: Nº | B4: DESCRIÇÃO | C4: R$ /item | D4: TAM. | E4: QTD | F4: R$ /estoque | G4: OBS.:
A5: 1 | B5: CALÇADO DE SEGURANÇA - TIPO BOTINA | C5: 104.29 | D5: 34 | E5: 0 | F5: =C5*E5 -> 0
A6: 2 | B6: CALÇADO DE SEGURANÇA - TIPO BOTINA | C6: 104.29 | D6: 35 | E6: 0 | F6: =C6*E6 -> 0
A7: 3 | B7: CALÇADO DE SEGURANÇA - TIPO BOTINA | C7: 104.29 | D7: 36 | E7: 0 | F7: =C7*E7 -> 0
A8: 4 | B8: CALÇADO DE SEGURANÇA - TIPO BOTINA | C8: 104.29 | D8: 37 | E8: 0 | F8: =C8*E8 -> 0
A9: 5 | B9: CALÇADO DE SEGURANÇA - TIPO BOTINA | C9: 104.29 | D9: 38 | E9: 2 | F9: =C9*E9 -> 208.58
A10: 6 | B10: CALÇADO DE SEGURANÇA - TIPO BOTINA | C10: 104.29 | D10: 39 | E10: 4 | F10: =C10*E10 -> 417.16
A11: 7 | B11: CALÇADO DE SEGURANÇA - TIPO BOTINA | C11: 104.29 | D11: 40 | E11: 5 | F11: =C11*E11 -> 521.45
A12: 8 | B12: CALÇADO DE SEGURANÇA - TIPO BOTINA | C12: 104.29 | D12: 41 | E12: 4 | F12: =C12*E12 -> 417.16
A13: 9 | B13: CALÇADO DE SEGURANÇA - TIPO BOTINA | C13: 104.29 | D13: 42 | E13: 4 | F13: =C13*E13 -> 417.16
A14: 10 | B14: CALÇADO DE SEGURANÇA - TIPO BOTINA | C14: 104.29 | D14: 43 | E14: 5 | F14: =C14*E14 -> 521.45
A15: 11 | B15: CALÇADO DE SEGURANÇA - TIPO BOTINA | C15: 104.29 | D15: 44 | E15: 3 | F15: =C15*E15 -> 312.87
A16: 12 | B16: CALÇADO DE SEGURANÇA - TIPO BOTINA | C16: 104.29 | D16: 45 | E16: 0 | F16: =C16*E16 -> 0
A17: 13 | B17: CALÇADO DE SEGURANÇA - TIPO BOTINA | C17: 104.29 | D17: 46 | E17: 0 | F17: =C17*E17 -> 0
A18: 14 | B18: CAPA DE CHUVA PVC AMARELA | C18: 40 | D18: P | E18: 0 | F18: =C18*E18 -> 0
A19: 15 | B19: CAPA DE CHUVA PVC AMARELA | C19: 40 | D19: M | E19: 4 | F19: =C19*E19 -> 160
A20: 16 | B20: CAPA DE CHUVA PVC AMARELA | C20: 40 | D20: G | E20: 7 | F20: =C20*E20 -> 280
A21: 17 | B21: CAPA DE CHUVA PVC AMARELA | C21: 40 | D21: GG | E21: 5 | F21: =C21*E21 -> 200
A22: 18 | B22: CHAVE DETECTORA DE TENSÃO | C22: 87.97 | E22: 0 | F22: =C22*E22 -> 0
A23: 19 | B23: CONE DE SINALIZAÇÃO (50 cm) | C23: 39 | E23: 8 | F23: =C23*E23 -> 312
A24: 21 | B24: LUVA DE VAQUETA CANO CURTO | C24: 38 | E24: 9 | F24: =C24*E24 -> 342
A25: 22 | B25: ÓCULOS DE SEGURANÇA - INCOLOR | C25: 4.85 | E25: 17 | F25: =C25*E25 -> 82.45
A26: 23 | B26: ÓCULOS DE SEGURANÇA - ESCURO | C26: 4 | E26: 4 | F26: =C26*E26 -> 16
A27: 24 | B27: COLETE DE SINALIZAÇÃO REFLETIVO | C27: 21 | E27: 10 | F27: =C27*E27 -> 210
A28: 25 | B28: GARRAFA TÉRMICA 3,5l | C28: 28.94 | E28: 6 | F28: =C28*E28 -> 173.64
A29: 26 | B29: PROTETOR SOLAR FPS 30 C/ REPELENTE (validade: ??) | C29: 15.19 | E29: 5 | F29: =C29*E29 -> 75.95
A30: 28 | B30: BALDE DE LONA | C30: 126.1 | E30: 10 | F30: =C30*E30 -> 1261
A31: 29 | B31: CAPACETE CLASSE B - ABA FRONTAL COM SUSPENSÃO E CATRACA | C31: 75 | E31: 9 | F31: =C31*E31 -> 675
A32: 30 | B32: CINTO DE SEGURANÇA MODELO PARAQUEDISTA TRABALHO EM ALTURA | C32: 584.2 | E32: 3 | F32: =C32*E32 -> 1752.6
A33: 31 | B33: SISTEMA DE RESGATE DE PESSOAS PARA ESCADA - KIT LVM | C33: 890.46 | E33: 3 | F33: =C33*E33 -> 2671.38
... A35: 33 | B35: TALABARTE DE PREVENÇÃO DE QUEDAS "Y" COM ABSORVEDOR | C35: 280.39 | E35: 0 | F35: =C35*E35 -> 0
A36: 34 | B36: TRAVA QUEDAS PARA CORDA 12MM | C36: 311.65 | E36: 3 | F36: =C36*E36 -> 934.95 | H36: ='ESTOQUE CWN - DF'!F46+'ESTOQUE CWN - MT'!F37+'ESTOQUE CWN - MS'!F54 -> 93932.98
A37: ESTOQUE PCD / TELETRABALHO
A38: 35 | B38: APOIO PARA OS PÉS | E38: 0
A39: 36 | B39: KEY PAD | E39: 0
A40: 37 | B40: MOUSE PAD | E40: 0
A41: 38 | B41: SUPORTE PARA NOTEBOOK | E41: 0
...

Sheet ESTOQUE CWN - MA
A1: Nome do Responsável Estoque - Tst ou Eng.: Luana
A2: Data da atualização da Planilha:15/06/2026
A3: Estoque da Cidade/Base: São Luis-MA
A4: Nº | B4: DESCRIÇÃO | C4: R$ /item | D4: TAM. | E4: QTD | F4: R$ /estoque | G4: OBS.:
A5: 1 | B5: ÁLCOOL GEL | D5: - | E5: 0 | F5: =C5*E5 -> 0
A6: 2 | B6: BALDE DE LONA | C6: ='ESTOQUE - SPO'!D6 -> 126.1 | D6: - | E6: 3 | F6: =C6*E6 -> 378.3
A7: 3 | B7: BOTA PVC LONGA 32 CM Nº 38 | C7: 69.9 | D7: 38 | E7: 0 | F7: =C7*E7 -> 0
A8: 4 | B8: BOTA PVC LONGA 32 CM Nº 39 | C8: 69.9 | D8: 39 | E8: 0 | F8: =C8*E8 -> 0
A9: 5 | B9: BOTA PVC LONGA 32 CM Nº 40 | C9: 69.9 | D9: 40 | E9: 0 | F9: =C9*E9 -> 0
A10: 6 | B10: BOTA PVC LONGA 32 CM Nº 41 | C10: 69.9 | D10: 41 | E10: 0 | F10: =C10*E10 -> 0
A11: 7 | B11: BOTA PVC LONGA 32 CM Nº 42 | C11: 69.9 | D11: 42 | E11: 0 | F11: =C11*E11 -> 0
A12: 8 | B12: BOTINA DE SEGURANCA SEM BIQUEIRA (VICHI) Nº 33 | C12: 104.29 | D12: 33 | E12: 0 | F12: =C12*E12 -> 0
A13: 9 | B13: BOTINA DE SEGURANCA SEM BIQUEIRA (VICHI) Nº 34 | C13: 104.29 | D13: 32 | E13: 0 | F13: =C13*E13 -> 0
A14: 10 | B14: BOTINA DE SEGURANCA SEM BIQUEIRA (VICHI) Nº 35 | C14: 104.29 | D14: 35 | E14: 0 | F14: =C14*E14 -> 0
A15: 11 | B15: BOTINA DE SEGURANCA SEM BIQUEIRA (VICHI) Nº 36 | C15: 104.29 | D15: 36 | E15: 6 | F15: =C15*E15 -> 625.74
A16: 12 | B16: BOTINA DE SEGURANCA SEM BIQUEIRA (VICHI) Nº 37 | C16: 104.29 | D16: 37 | E16: 6 | F16: =C16*E16 -> 625.74
A17: 13 | B17: BOTINA DE SEGURANCA SEM BIQUEIRA (VICHI) Nº 38 | C17: 104.29 | D17: 38 | E17: 6 | F17: =C17*E17 -> 625.74
A18: 14 | B18: BOTINA DE SEGURANCA SEM BIQUEIRA (VICHI) Nº 39 | C18: 104.29 | D18: 39 | E18: 8 | F18: =C18*E18 -> 834.32
... A26: 22 | B26: BOTINA DE SEGURANCA SEM BIQUEIRA (VICHI) Nº 48 | C26: 104.29 | D26: 48 | E26: 0 | F26: =C26*E26 -> 0
A27: 23 | B27: CAPA DE CHUVA COM CAPUZ AMARELA | C27: 40 | E27: 6 | F27: =C27*E27 -> 240
A28: 24 | B28: CAPACETE ALPINISTA SEM ABA | C28: 180.93 | D28: - | E28: 0 | F28: =C28*E28 -> 0
A29: 25 | B29: CAPACETE CLASSE B - ABA FRONTAL | C29: 75 | D29: - | E29: 8 | F29: =C29*E29 -> 600
A30: 26 | B30: CARNEIRA + CATRACA PARA CAPACETE | C30: 48.25 | D30: - | E30: 11 | F30: =C30*E30 -> 530.75
A31: 27 | B31: CHAVE DETECTORA DE TENSÃO | C31: 87.97 | D31: - | E31: 14 | F31: =C31*E31 -> 1231.58
A32: 28 | B32: CINTO DE SEGURANÇA - TELECOM | C32: 584.2 | D32: - | E32: 5 | F32: =C32*E32 -> 2921
A33: 29 | B33: COLETE DE SINALIZAÇÃO | C33: 21 | D33: - | E33: 12 | F33: =C33*E33 -> 252
A34: 30 | B34: CONE DE SINALIZAÇÃO BORRACHA, LARANJA/BRANCO, 50 CM | C34: 39 | D34: - | E34: 12 | F34: =C34*E34 -> 468
A35: 31 | B35: FITA DE ANCORAGEM AMARELA | C35: 81.83 | D35: - | E35: 0 | F35: =C35*E35 -> 0
A36: 32 | B36: GARRAFA TÉRMICA – 3,5 | C36: 28.94 | D36: - | E36: 6 | F36: =C36*E36 -> 173.64
A37: 33 | B37: JUGULAR TECIDO CAPACETE 3M | C37: 8.63 | D37: - | E37: 21 | F37: =C37*E37 -> 181.23
A38: 34 | B38: LUVA DE SEGURANÇA PU ANTICORTE P | C38: 267.69 | E38: 0 | F38: =C38*E38 -> 0
A39: 35 | B39: LUVA DE SEGURANÇA PU ANTICORTE M | C39: 267.69 | E39: 6 | F39: =C39*E39 -> 1606.14
A40: 36 | B40: LUVA DE SEGURANÇA PU ANTICORTE G | C40: 9.8 | E40: 5 | F40: =C41*E40 -> 153.3
A41: 37 | B41: LUVA DE SEGURANÇA PU ANTICORTE XG | C41: 30.66 | E41: 1 | F41: =C42*E41 -> 38
A42: 38 | B42: LUVA DE VAQUETA CANO CURTO | C42: 38 | E42: 16 | F42: =C42*E42 -> 608
A43: 39 | B43: LUVA DE VAQUETA CONFORT SEM DEDO | C43: 36.31 | E43: 0 | F43: =C43*E43 -> 0
A44: 40 | B44: LUVA PIGMENTADA | C44: 23.7 | E44: 0
A45: 41 | B45: MÁSCARA DE PANO - ROXA VIVO (pacote com 5) | D45: - | E45: 0 | F45: =C45*E45 -> 0
A46: 42 | B46: MOSQUETÃO OVAL AÇO TRAVA ROSCA | C46: 62.14 | D46: - | E46: 0 | F46: =C46*E46 -> 0
A47: 43 | B47: ÓCULOS DE SEGURANÇA - FUMÊ | C47: 4 | E47: 3 | F47: =C47*E47 -> 12
...

Sheet ESTOQUE CWN - GO
A1: Nome do Responsável Estoque - Tst ou Eng.: Camila Martins Silva
A2: Data da atualização da Planilha: 05/09/2025
A3: Estoque da Cidade/Base: GO
A4: Nº | B4: DESCRIÇÃO | C4: R$ /item | D4: TAM. | E4: QTD | F4: R$ /estoque | G4: OBS.:
A5: 1 | B5: CALÇADO DE SEGURANÇA - TIPO BOTINA | C5: 104.29 | D5: 34 | E5: 0 | F5: =C5*E5 -> 0
A6: 2 | B6: CALÇADO DE SEGURANÇA - TIPO BOTINA | C6: 104.29 | D6: 35 | E6: 0 | F6: =C6*E6 -> 0
A7: 3 | B7: CALÇADO DE SEGURANÇA - TIPO BOTINA | C7: 104.29 | D7: 36 | E7: 0 | F7: =C7*E7 -> 0
A8: 4 | B8: CALÇADO DE SEGURANÇA - TIPO BOTINA | C8: 104.29 | D8: 37 | E8: 0 | F8: =C8*E8 -> 0
A9: 5 | B9: CALÇADO DE SEGURANÇA - TIPO BOTINA | C9: 104.29 | D9: 38 | E9: 18 | F9: =C9*E9 -> 1877.22
A10: 6 | B10: CALÇADO DE SEGURANÇA - TIPO BOTINA | C10: 104.29 | D10: 39 | E10: 28 | F10: =C10*E10 -> 2920.12
A11: 7 | B11: CALÇADO DE SEGURANÇA - TIPO BOTINA | C11: 104.29 | D11: 40 | E11: 8 | F11: =C11*E11 -> 834.32
A12: 8 | B12: CALÇADO DE SEGURANÇA - TIPO BOTINA | C12: 104.29 | D12: 41 | E12: 11 | F12: =C12*E12 -> 1147.19
A13: 9 | B13: CALÇADO DE SEGURANÇA - TIPO BOTINA | C13: 104.29 | D13: 42 | E13: 16 | F13: =C13*E13 -> 1668.64
A14: 10 | B14: CALÇADO DE SEGURANÇA - TIPO BOTINA | C14: 104.29 | D14: 43 | E14: 0 | F14: =C14*E14 -> 0
A15: 11 | B15: CALÇADO DE SEGURANÇA - TIPO BOTINA | C15: 104.29 | D15: 44 | E15: 5 | F15: =C15*E15 -> 521.45
A16: 12 | B16: CALÇADO DE SEGURANÇA - TIPO BOTINA | C16: 104.29 | D16: 45 | E16: 0 | F16: =C16*E16 -> 0
A17: 13 | B17: CALÇADO DE SEGURANÇA - TIPO BOTINA | C17: 104.29 | D17: 46 | E17: 1 | F17: =C17*E17 -> 104.29
A18: 14 | B18: CAPA DE CHUVA PVC AMARELA | C18: 40 | D18: P | E18: 0 | F18: =C18*E18 -> 0
A19: 15 | B19: CAPA DE CHUVA PVC AMARELA | C19: 40 | D19: M | E19: 13 | F19: =C19*E19 -> 520
A20: 16 | B20: CAPA DE CHUVA PVC AMARELA | C20: 40 | D20: G | E20: 19 | F20: =C20*E20 -> 760
A21: 17 | B21: CAPA DE CHUVA PVC AMARELA | C21: 40 | D21: GG | E21: 0 | F21: =C21*E21 -> 0
A22: 18 | B22: CHAVE DETECTORA DE TENSÃO | C22: 87.97 | E22: 87 | F22: =C22*E22 -> 7653.39
A23: 19 | B23: CONE DE SINALIZAÇÃO (50 cm) | C23: 39 | E23: 16 | F23: =C23*E23 -> 624
A24: 21 | B24: LUVA DE VAQUETA CANO CURTO | C24: 38 | E24: 65 | F24: =C24*E24 -> 2470
A25: 22 | B25: ÓCULOS DE SEGURANÇA - INCOLOR | C25: 4.85 | E25: 59 | F25: =C25*E25 -> 286.15
A26: 23 | B26: ÓCULOS DE SEGURANÇA - ESCURO | C26: 4 | E26: 39 | F26: =C26*E26 -> 156
A27: 24 | B27: COLETE DE SINALIZAÇÃO REFLETIVO | C27: 21 | E27: 50 | F27: =C27*E27 -> 1050
A28: 25 | B28: GARRAFA TÉRMICA 3,5l | C28: 28.94 | E28: 13 | F28: =C28*E28 -> 376.22
A29: 26 | B29: PROTETOR SOLAR FPS 30 C/ REPELENTE (validade: ??) | C29: 15.19 | E29: 66 | F29: =C29*E29 -> 1002.54
A30: 28 | B30: BALDE DE LONA | C30: 126.1 | E30: 39 | F30: =C30*E30 -> 4917.9
A31: 29 | B31: CAPACETE CLASSE B - ABA FRONTAL COM SUSPENSÃO E CATRACA | C31: 75 | E31: 14 | F31: =C31*E31 -> 1050
A32: 30 | B32: CINTO DE SEGURANÇA MODELO PARAQUEDISTA TRABALHO EM ALTURA | C32: 584.2 | E32: 32 | F32: =C32*E32 -> 18694.4
A33: 31 | B33: SISTEMA DE RESGATE DE PESSOAS PARA ESCADA - KIT LVM | C33: 890.46 | E33: 4 | F33: =C33*E33 -> 3561.84
... A35: 33 | B35: TALABARTE DE PREVENÇÃO DE QUEDAS "Y" COM ABSORVEDOR | C35: 280.39 | E35: 4 | F35: =C35*E35 -> 1121.56
A36: 34 | B36: TRAVA QUEDAS PARA CORDA 12MM | C36: 311.65 | E36: 16 | F36: =C36*E36 -> 4986.4 | H36: ='ESTOQUE CWN - DF'!F46+'ESTOQUE CWN - MT'!F37+'ESTOQUE CWN - MS'!F54 -> 93932.98
A37: ESTOQUE PCD / TELETRABALHO
A38: 35 | B38: APOIO PARA OS PÉS | E38: 0
A39: 36 | B39: KEY PAD | E39: 0
A40: 37 | B40: MOUSE PAD | E40: 0
A41: 38 | B41: SUPORTE PARA NOTEBOOK | E41: 0
...

Sheet ESTOQUE CWN - MT
A1: Nome do Responsável Estoque - Tst ou Eng.: Luana
A2: Data da atualização da Planilha: 28/08/2025
A3: Estoque da Cidade/Base: VIVO CUIABÁ
A4: Nº | B4: DESCRIÇÃO | C4: R$ /item | D4: TAM. | E4: QTD | F4: R$ /estoque | G4: OBS.:
A5: 1 | B5: BALDE DE LONA | C5: 126.1 | D5: - | E5: 8 | F5: =C5*E5 -> 1008.8
A6: 2 | B6: CALÇADO DE SEGURANÇA - TIPO BOTINA | C6: 104.29 | D6: 34 | E6: 0 | F6: =C6*E6 -> 0
A7: 3 | B7: CALÇADO DE SEGURANÇA - TIPO BOTINA | C7: 104.29 | D7: 35 | E7: 0 | F7: =C7*E7 -> 0
A8: 4 | B8: CALÇADO DE SEGURANÇA - TIPO BOTINA | C8: 104.29 | D8: 36 | E8: 2 | F8: =C8*E8 -> 208.58
A9: 5 | B9: CALÇADO DE SEGURANÇA - TIPO BOTINA | C9: 104.29 | D9: 37 | E9: 6 | F9: =C9*E9 -> 625.74
A10: 6 | B10: CALÇADO DE SEGURANÇA - TIPO BOTINA | C10: 104.29 | D10: 38 | E10: 6 | F10: =C10*E10 -> 625.74
A11: 7 | B11: CALÇADO DE SEGURANÇA - TIPO BOTINA | C11: 104.29 | D11: 39 | E11: 5 | F11: =C11*E11 -> 521.45
A12: 8 | B12: CALÇADO DE SEGURANÇA - TIPO BOTINA | C12: 104.29 | D12: 40 | E12: 3 | F12: =C12*E12 -> 312.87
A13: 9 | B13: CALÇADO DE SEGURANÇA - TIPO BOTINA | C13: 104.29 | D13: 41 | E13: 2 | F13: =C13*E13 -> 208.58
A14: 10 | B14: CALÇADO DE SEGURANÇA - TIPO BOTINA | C14: 104.29 | D14: 42 | E14: 3 | F14: =C14*E14 -> 312.87
A15: 11 | B15: CALÇADO DE SEGURANÇA - TIPO BOTINA | C15: 104.29 | D15: 43 | E15: 4 | F15: =C15*E15 -> 417.16
A16: 12 | B16: CALÇADO DE SEGURANÇA - TIPO BOTINA | C16: 104.29 | D16: 44 | E16: 2 | F16: =C16*E16 -> 208.58
A17: 13 | B17: CALÇADO DE SEGURANÇA - TIPO BOTINA | C17: 104.29 | D17: 45 | E17: 0 | F17: =C17*E17 -> 0
A18: 14 | B18: CALÇADO DE SEGURANÇA - TIPO BOTINA | C18: 104.29 | D18: 46 | E18: 1 | F18: =C18*E18 -> 104.29
A19: 15 | B19: CAPA DE CHUVA PVC AMARELA | C19: 40 | D19: P | E19: 8 | F19: =C19*E19 -> 320
A20: 16 | B20: CAPA DE CHUVA PVC AMARELA | C20: 40 | D20: M | E20: 12 | F20: =C20*E20 -> 480
A21: 17 | B21: CAPA DE CHUVA PVC AMARELA | C21: 40 | D21: G | E21: 80 | F21: =C21*E21 -> 3200
A22: 18 | B22: CAPA DE CHUVA PVC AMARELA | C22: 40 | D22: GG | E22: 40 | F22: =C22*E22 -> 1600
A23: 19 | B23: CAPACETE CLASSE B - ABA FRONTAL | C23: 75 | D23: - | E23: 13 | F23: =C23*E23 -> 975
A24: 20 | B24: CARNEIRA + CATRACA | C24: 48.25 | D24: - | E24: 28 | F24: =C24*E24 -> 1351
A25: 21 | B25: CHAVE DETECTORA DE TENSÃO | C25: 87.97 | D25: - | E25: 20 | F25: =C25*E25 -> 1759.4
A26: 22 | B26: CINTO DE SEGURANÇA TRABALHO EM ALTURA | C26: 584.2 | D26: - | E26: 10 | F26: =C26*E26 -> 5842
A27: 23 | B27: COLETE DE SINALIZAÇÃO REFLETIVO | C27: 21 | D27: - | E27: 28 | F27: =C27*E27 -> 588
A28: 24 | B28: CONE DE SINALIZAÇÃO (50 cm) | C28: 39 | D28: - | E28: 65 | F28: =C28*E28 -> 2535
A29: 25 | B29: GARRAFA TÉRMICA 3,5l | C29: 28.94 | D29: - | E29: 30 | F29: =C29*E29 -> 868.2
A30: 26 | B30: JUGULAR TECIDO PARA CAPACETE 3M | C30: 8.63 | D30: - | E30: 15 | F30: =C30*E30 -> 129.45
A31: 27 | B31: LUVA DE SEGURANÇA PU ANTICORTE P | C31: 30.66 | E31: 8 | F31: =C31*E31 -> 245.28
A32: 28 | B32: LUVA DE SEGURANÇA PU ANTICORTE M | E32: 10 | F32: =C32*E32 -> 0
A33: 29 | B33: LUVA DE SEGURANÇA PU ANTICORTE G | E33: 0 | F33: =C33*E33 -> 0
B34: LUVA DE SEGURANÇA PU ANTICORTE XG | E34: 20 | F34: =C34*E34 -> 0
A35: 28 | B35: LUVA DE VAQUETA CANO CURTO | C35: 38 | D35: - | E35: 40 | F35: =C35*E35 -> 1520
A36: 29 | B36: ÓCULOS DE SEGURANÇA - ESCURO | C36: 4.85 | D36: - | E36: 15 | F36: =C36*E36 -> 72.75
A37: 30 | B37: ÓCULOS DE SEGURANÇA - ESCURO SOBREPOR | C37: 9 | D37: - | E37: 10 | F37: =C37*E37 -> 90
A38: 31 | B38: ÓCULOS DE SEGURANÇA - INCOLOR | C38: 4 | D38: - | E38: 20 | F38: =C38*E38 -> 80
A39: 32 | B39: ÓCULOS DE SEGURANÇA - INCOLOR SOBREPOR | C39: 8.08 | D39: - | E39: 22 | F39: =C39*E39 -> 177.76
A40: 33 | B40: PROTETOR SOLAR FPS 30 C/ REPELENTE (Validade: XX/XX) | C40: 15.19 | D40: - | E40: 0 | F40: =C40*E40 -> 0
...

Sheet ESTOQUE CWN - MS
A1: Nome do Responsável Estoque - Tst ou Eng.: Camila Martins Silva
A2: Data da atualização da Planilha: 05/09/2025
A3: Estoque da Cidade/Base: Campo Grande MS
A4: Nº | B4: DESCRIÇÃO | C4: R$ /item | D4: TAM. | E4: QTD | F4: R$ /estoque | G4: OBS.:
A5: 1 | B5: CALÇADO DE SEGURANÇA - TIPO BOTINA | C5: 104.29 | D5: 34 | E5: 0 | F5: =C5*E5 -> 0
A6: 2 | B6: CALÇADO DE SEGURANÇA - TIPO BOTINA | C6: 104.29 | D6: 35 | E6: 0 | F6: =C6*E6 -> 0
A7: 3 | B7: CALÇADO DE SEGURANÇA - TIPO BOTINA | C7: 104.29 | D7: 36 | E7: 0 | F7: =C7*E7 -> 0
A8: 4 | B8: CALÇADO DE SEGURANÇA - TIPO BOTINA | C8: 104.29 | D8: 37 | E8: 15 | F8: =C8*E8 -> 1564.35
A9: 5 | B9: CALÇADO DE SEGURANÇA - TIPO BOTINA | C9: 104.29 | D9: 38 | E9: 6 | F9: =C9*E9 -> 625.74
A10: 6 | B10: CALÇADO DE SEGURANÇA - TIPO BOTINA | C10: 104.29 | D10: 39 | E10: 15 | F10: =C10*E10 -> 1564.35
A11: 7 | B11: CALÇADO DE SEGURANÇA - TIPO BOTINA | C11: 104.29 | D11: 40 | E11: 20 | F11: =C11*E11 -> 2085.8
A12: 8 | B12: CALÇADO DE SEGURANÇA - TIPO BOTINA | C12: 104.29 | D12: 41 | E12: 20 | F12: =C12*E12 -> 2085.8
A13: 9 | B13: CALÇADO DE SEGURANÇA - TIPO BOTINA | C13: 104.29 | D13: 42 | E13: 8 | F13: =C13*E13 -> 834.32
A14: 10 | B14: CALÇADO DE SEGURANÇA - TIPO BOTINA | C14: 104.29 | D14: 43 | E14: 11 | F14: =C14*E14 -> 1147.19
A15: 11 | B15: CALÇADO DE SEGURANÇA - TIPO BOTINA | C15: 104.29 | D15: 44 | E15: 10 | F15: =C15*E15 -> 1042.9
A16: 12 | B16: CALÇADO DE SEGURANÇA - TIPO BOTINA | C16: 104.29 | D16: 45 | E16: 2 | F16: =C16*E16 -> 208.58
A17: 13 | B17: CALÇADO DE SEGURANÇA - TIPO BOTINA | C17: 104.29 | D17: 46 | E17: 4 | F17: =C17*E17 -> 417.16
A18: 14 | B18: CAPA DE CHUVA PVC AMARELA | C18: 40 | D18: P | E18: 0 | F18: =C18*E18 -> 0
A19: 15 | B19: CAPA DE CHUVA PVC AMARELA | C19: 40 | D19: M | E19: 0 | F19: =C19*E19 -> 0
A20: 16 | B20: CAPA DE CHUVA PVC AMARELA | C20: 40 | D20: G | E20: 0 | F20: =C20*E20 -> 0
A21: 17 | B21: CAPA DE CHUVA PVC AMARELA | C21: 40 | D21: GG | E21: 28 | F21: =C21*E21 -> 1120
A22: 18 | B22: CHAVE DETECTORA DE TENSÃO | C22: 87.97 | E22: 50 | F22: =C22*E22 -> 4398.5
A23: 19 | B23: CONE DE SINALIZAÇÃO (50 cm) | C23: 39 | E23: 70 | F23: =C23*E23 -> 2730
A24: 21 | B24: LUVA DE VAQUETA CANO CURTO | C24: 38 | E24: 160 | F24: =C24*E24 -> 6080
A25: 22 | B25: ÓCULOS DE SEGURANÇA - INCOLOR | C25: 4.85 | E25: 300 | F25: =C25*E25 -> 1455
A26: 23 | B26: ÓCULOS DE SEGURANÇA - ESCURO | C26: 4 | E26: 50 | F26: =C26*E26 -> 200
A27: 24 | B27: COLETE DE SINALIZAÇÃO REFLETIVO | C27: 21 | E27: 55 | F27: =C27*E27 -> 1155
A28: 25 | B28: GARRAFA TÉRMICA | C28: 28.94 | E28: 29 | F28: =C28*E28 -> 839.26
A29: 26 | B29: PROTETOR SOLAR FPS 30 C/ REPELENTE - 1- nutriex (venc. 06/2026) 2- nutriex (venc. 10/2024) 3- sunlau (12/2022) | C29: 15.19 | E29: 251 | F29: =C29*E29 -> 3812.69
A30: 27 | B30: BALDE DE LONA | C30: 126.1 | E30: 32 | F30: =C30*E30 -> 4035.2
A31: 28 | B31: CAPACETE CLASSE B - ABA FRONTAL COM SUSPENSÃO E CATRACA | C31: 75 | E31: 10 | F31: =C31*E31 -> 750
A32: 29 | B32: CINTO DE SEGURANÇA MODELO PARAQUEDISTA TRABALHO EM ALTURA | C32: 584.2 | E32: 10 | F32: =C32*E32 -> 5842
A33: 30 | B33: SISTEMA DE RESGATE DE PESSOAS PARA ESCADA - KIT LVM | C33: 890.46 | E33: 49 | F33: =C33*E33 -> 43632.54
... A36: 33 | B36: TRAVA QUEDAS PARA CORDA 12MM | C36: 311.65 | E36: 4 | F36: =C36*E36 -> 1246.6
A37: 34 | B37: ABAFADOR DE OUVIDOS | E37: 2
A38: 35 | B38: BANDEIROLA | E38: 77
A39: 36 | B39: BOLSA EM LONA BOCA ABERTA VIVO NEW | E39: 20
A40: 37 | B40: CARNEIRA | E40: 10
A41: 38 | B41: FITA ZEBRADA | E41: 9
A42: 39 | B42: GARRA MEIO DE VÃO | E42: 20
...

Sheet ESTOQUE NDT - BA
A1: Nome do Responsável Estoque - Tst ou Eng.: Marcus Pitanga
A2: Data da atualização da Planilha: 29.08.2025
A3: Estoque da Cidade/Base: Salvador/BA
A4: Nº | B4: DESCRIÇÃO | C4: R$ /item | D4: TAM. | E4: QTD | F4: R$ /estoque | G4: OBS.:
B5: BOTA PVC LONGA 32 CM Nº 38 | C5: 69.9 | D5: 38 | E5: 0 | F5: =C5*E5 -> 0 | G5: Gostaria de umas de estoque
B6: BOTA PVC LONGA 32 CM Nº 39 | C6: 69.9 | D6: 39 | E6: 0 | F6: =C6*E6 -> 0 | G6: Gostaria de umas de estoque
B7: BOTA PVC LONGA 32 CM Nº 40 | C7: 69.9 | D7: 40 | E7: 0 | F7: =C7*E7 -> 0 | G7: Gostaria de umas de estoque
B8: BOTA PVC LONGA 32 CM Nº 41 | C8: 69.9 | D8: 41 | E8: 0 | F8: =C8*E8 -> 0 | G8: Gostaria de umas de estoque
B9: BOTA PVC LONGA 32 CM Nº 42 | C9: 69.9 | D9: 42 | E9: 0 | F9: =C9*E9 -> 0 | G9: Gostaria de umas de estoque
B10: CALÇADO DE SEGURANÇA - TIPO BOTINA | C10: 104.29 | D10: 34 | E10: 5 | F10: =E10*C10 -> 521.45
B11: CALÇADO DE SEGURANÇA - TIPO BOTINA | C11: 104.29 | D11: 35 | E11: 5 | F11: =E11*C11 -> 521.45
B12: CALÇADO DE SEGURANÇA - TIPO BOTINA | C12: 104.29 | D12: 36 | E12: 10 | F12: =E12*C12 -> 1042.9
B13: CALÇADO DE SEGURANÇA - TIPO BOTINA | C13: 104.29 | D13: 37 | E13: 10 | F13: =E13*C13 -> 1042.9
B14: CALÇADO DE SEGURANÇA - TIPO BOTINA | C14: 104.29 | D14: 38 | E14: 5 | F14: =E14*C14 -> 521.45
B15: CALÇADO DE SEGURANÇA - TIPO BOTINA | C15: 104.29 | D15: 39 | E15: 10 | F15: =E15*C15 -> 1042.9
B16: CALÇADO DE SEGURANÇA - TIPO BOTINA | C16: 104.29 | D16: 40 | E16: 5 | F16: =E16*C16 -> 521.45
B17: CALÇADO DE SEGURANÇA - TIPO BOTINA | C17: 104.29 | D17: 41 | E17: 10 | F17: =E17*C17 -> 1042.9
B18: CALÇADO DE SEGURANÇA - TIPO BOTINA | C18: 104.29 | D18: 42 | E18: 0 | F18: =E18*C18 -> 0 | G18: Gostaria de umas de estoque
B19: CALÇADO DE SEGURANÇA - TIPO BOTINA | C19: 104.29 | D19: 43 | E19: 0 | F19: =E19*C19 -> 0 | G19: Gostaria de umas de estoque
B20: CALÇADO DE SEGURANÇA - TIPO BOTINA | C20: 104.29 | D20: 44 | E20: 3 | F20: =E20*C20 -> 312.87 | G20: Gostaria de umas de estoque
B21: CALÇADO DE SEGURANÇA - TIPO BOTINA | C21: 104.29 | D21: 45 | E21: 3 | F21: =E21*C21 -> 312.87
B22: CALÇADO DE SEGURANÇA - TIPO BOTINA | C22: 104.29 | D22: 46 | E22: 3 | F22: =E22*C22 -> 312.87
B23: CALÇADO DE SEGURANÇA - TIPO BOTINA | C23: 104.29 | D23: 47 | E23: 0 | F23: =E23*C23 -> 0
B24: CALÇADO DE SEGURANÇA - TIPO BOTINA | C24: 104.29 | D24: 48 | E24: 0 | F24: =E24*C24 -> 0
B25: CAPA DE CHUVA PVC AMARELA | C25: 40 | D25: P | E25: 0 | F25: =E25*C25 -> 0
B26: CAPA DE CHUVA PVC AMARELA | C26: 40 | D26: M | E26: 0 | F26: =E26*C26 -> 0
B27: CAPA DE CHUVA PVC AMARELA | C27: 40 | D27: G | E27: 3 | F27: =E27*C27 -> 120 | G27: Gostaria de umas de estoque
B28: CAPA DE CHUVA PVC AMARELA | C28: 40 | D28: GG | E28: 0 | F28: =E28*C28 -> 0
B29: CHAVE DETECTORA DE TENSÃO | C29: 87.97 | E29: 3 | F29: =E29*C29 -> 263.91 | G29: Gostaria de estoque
B30: CONE DE SINALIZAÇÃO (50 cm) | C30: 39 | E30: 10 | F30: =E30*C30 -> 390 | G30: Gostaria de estoque
B31: LUVA DE VAQUETA CANO CURTO | C31: 38 | E31: 5 | F31: =E31*C31 -> 190 | G31: Gostaria de estoque
B32: LUVA DE PVC CANO CURTO VERDE | C32: 9.8 | D32: G | E32: 0 | F32: =C32*E32 -> 0 | G32: Gostaria de estoque
B33: LUVA DE MALHA PU ANTICORTE | C33: 35.89 | D33: P | E33: 3 | F33: =E33*C33 -> 107.67 | G33: Gostaria de estoque
B34: LUVA DE MALHA PU ANTICORTE | C34: 35.89 | D34: M | E34: 0 | F34: =E34*C34 -> 0 | G34: Gostaria de estoque
B35: LUVA DE MALHA PU ANTICORTE | C35: 35.89 | D35: G | E35: 15 | F35: =E35*C35 -> 538.35 | G35: Gostaria de estoque
B36: LUVA DE MALHA PU ANTICORTE | C36: 35.89 | D36: XG | E36: 15 | F36: =E36*C36 -> 538.35 | G36: Gostaria de estoque
B37: TOUCA ÁRABE | C37: 0 | D37: UNI | E37: 0 | F37: =E37*C37 -> 0 | G37: Gostaria de estoque
B38: BANDEIROLA DE SINALIZAÇÃO SEM CABO | C38: 22.19 | D38: UNI | E38: 0 | F38: =E38*C38 -> 0 | G38: Gostaria de estoque
B39: ÓCULOS DE SEGURANÇA - INCOLOR | C39: 4.85 | E39: 10 | F39: =E39*C39 -> 48.5 | G39: Gostaria de estoque
B40: ÓCULOS DE SEGURANÇA - ESCURO | C40: 4 | E40: 10 | F40: =E40*C40 -> 40 | G40: Gostaria de estoque
...

Sheet ESTOQUE NDT - CE
A1: Nome do Responsável Estoque - Tst ou Eng.: Raphael Meneses
A2: Data da atualização da Planilha: 22/09/2023
A3: Estoque da Cidade/Base: Fortaleza
A4: Nº | B4: DESCRIÇÃO | C4: R$ /item | D4: TAM. | E4: QTD | F4: R$ /estoque | G4: OBS.:
A5: 1 | B5: CALÇADO DE SEGURANÇA - TIPO BOTINA | C5: 104.29 | D5: 34 | E5: 1 | F5: =E5*C5 -> 104.29
A6: 2 | B6: CALÇADO DE SEGURANÇA - TIPO BOTINA | C6: 104.29 | D6: 35 | E6: 5 | F6: =E6*C6 -> 521.45
A7: 3 | B7: CALÇADO DE SEGURANÇA - TIPO BOTINA | C7: 104.29 | D7: 36 | E7: 12 | F7: =E7*C7 -> 1251.48
